<?xml version="1.0" encoding="UTF-8"?>
<robot name="frank_right_closed">
  <joint name="FixedJoint" type="fixed">
    <origin xyz="0. 0. 0.91694" rpy="0. 0. 0."/>
    <parent link="base_link"/>
    <child link="ewellix_lift_top_link"/>
  </joint>
  <joint name="left_arm_left_finger_mount_fixed_joint" type="fixed">
    <origin xyz="-0.0000448 -0.0057711 0.03995 " rpy="-1.5707964 0. -1.5699061"/>
    <parent link="left_arm_left_inner_finger"/>
    <child link="left_arm_left_finger_mount"/>
  </joint>
  <joint name="left_arm_left_fingertip_fixed_joint" type="fixed">
    <origin xyz="0.0184435 0.01721 0.0129684" rpy="1.5707964 0. -3.1415925"/>
    <parent link="left_arm_left_finger_mount"/>
    <child link="left_arm_left_fingertip"/>
  </joint>
  <joint name="left_arm_left_inner_knuckle_finger_joint" type="fixed">
    <origin xyz="-0.0000052 -0.0682011 0.0979099" rpy="0. 0. 3.1415052"/>
    <parent link="left_arm_left_inner_knuckle"/>
    <child link="left_arm_left_inner_finger"/>
  </joint>
  <joint name="left_arm_left_inner_knuckle_joint" type="fixed">
    <origin xyz="0. 0. 0." rpy="0. 0. -0.0000066"/>
    <parent link="left_arm_robotiq_arg2f_base_link"/>
    <child link="left_arm_left_inner_knuckle"/>
  </joint>
  <joint name="left_arm_left_outer_finger_joint" type="fixed">
    <origin xyz="0.0000019 -0.0621011 0.0508099" rpy="0. 0. 3.1415055"/>
    <parent link="left_arm_left_outer_knuckle"/>
    <child link="left_arm_left_outer_finger"/>
  </joint>
  <joint name="left_arm_left_outer_knuckle_joint" type="fixed">
    <origin xyz="0. 0. 0." rpy="0. 0. -0.0000066"/>
    <parent link="left_arm_robotiq_arg2f_base_link"/>
    <child link="left_arm_left_outer_knuckle"/>
  </joint>
  <joint name="left_arm_right_finger_mount_fixed_joint" type="fixed">
    <origin xyz="-0.0000599 0.0497321 0.07644 " rpy="-1.5707963 0. -1.5699935"/>
    <parent link="left_arm_right_inner_finger"/>
    <child link="left_arm_right_finger_mount"/>
  </joint>
  <joint name="left_arm_right_fingertip_fixed_joint" type="fixed">
    <origin xyz="0.0183902 0.01721 0.0129937" rpy="1.5707964 0. 3.1415925"/>
    <parent link="left_arm_right_finger_mount"/>
    <child link="left_arm_right_fingertip"/>
  </joint>
  <joint name="left_arm_right_inner_knuckle_finger_joint" type="fixed">
    <origin xyz="-0.0000002 0.0127 0.06142 " rpy="0. 0. 0."/>
    <parent link="left_arm_right_inner_knuckle"/>
    <child link="left_arm_right_inner_finger"/>
  </joint>
  <joint name="left_arm_right_inner_knuckle_joint" type="fixed">
    <origin xyz="0. 0. 0." rpy="0. 0. -0.0000066"/>
    <parent link="left_arm_robotiq_arg2f_base_link"/>
    <child link="left_arm_right_inner_knuckle"/>
  </joint>
  <joint name="left_arm_right_outer_finger_joint" type="fixed">
    <origin xyz="-0.0000045 0.0621011 0.05081 " rpy="0. 0. 0."/>
    <parent link="left_arm_right_outer_knuckle"/>
    <child link="left_arm_right_outer_finger"/>
  </joint>
  <joint name="left_arm_right_outer_knuckle_joint" type="fixed">
    <origin xyz="0. 0. 0." rpy="0. 0. -0.0000066"/>
    <parent link="left_arm_robotiq_arg2f_base_link"/>
    <child link="left_arm_right_outer_knuckle"/>
  </joint>
  <joint name="left_end_effector" type="fixed">
    <origin xyz="-0.0615251 0.0000052 0. " rpy="-3.1415925 0. -0.0000037"/>
    <parent link="left_bracelet_link"/>
    <child link="left_end_effector_link"/>
  </joint>
  <joint name="left_gripper_base_joint" type="fixed">
    <origin xyz="0.0000051 0. 0. " rpy="-1.5707964 -0.0007963 1.5707963"/>
    <parent link="left_end_effector_link"/>
    <child link="left_arm_robotiq_arg2f_base_link"/>
  </joint>
  <joint name="left_joint_1" type="revolute">
    <origin xyz="0. 0.18643 0.17446" rpy="1.5707964 0.0000072 -1.5707964"/>
    <parent link="left_base_link"/>
    <child link="left_shoulder_link"/>
    <axis xyz="1. 0. 0."/>
    <limit lower="-5.9999991" upper="5.9999991" effort="39." velocity="1.3963"/>
  </joint>
  <joint name="left_joint_2" type="revolute">
    <origin xyz="-0.12838 0.0053741 0. " rpy="0. 0. -1.5707927"/>
    <parent link="left_shoulder_link"/>
    <child link="left_half_arm_1_link"/>
    <axis xyz="1. 0. 0."/>
    <limit lower="-2.4099997" upper="2.4099997" effort="39." velocity="1.3963"/>
  </joint>
  <joint name="left_joint_3" type="revolute">
    <origin xyz="-0.0063793 -0.21038 0. " rpy="0. 0. 1.5708035"/>
    <parent link="left_half_arm_1_link"/>
    <child link="left_half_arm_2_link"/>
    <axis xyz="1. 0. 0."/>
    <limit lower="-5.9999991" upper="5.9999991" effort="39." velocity="1.3963"/>
  </joint>
  <joint name="left_joint_4" type="revolute">
    <origin xyz="-0.21038 0.0063708 0. " rpy="0. 0. -1.5708035"/>
    <parent link="left_half_arm_2_link"/>
    <child link="left_forearm_link"/>
    <axis xyz="1. 0. 0."/>
    <limit lower="-2.6599997" upper="2.6599997" effort="39." velocity="1.3963"/>
  </joint>
  <joint name="left_joint_5" type="revolute">
    <origin xyz="-0.0063793 -0.20843 0. " rpy="-0.0011345 0.0000349 1.5708034"/>
    <parent link="left_forearm_link"/>
    <child link="left_spherical_wrist_1_link"/>
    <axis xyz="1. 0. 0."/>
    <limit lower="-5.9999991" upper="5.9999991" effort="9." velocity="1.2218"/>
  </joint>
  <joint name="left_joint_6" type="revolute">
    <origin xyz="-0.10593 0.0001804 -0.0000035" rpy="0.0000348 0.0011344 -1.5708034"/>
    <parent link="left_spherical_wrist_1_link"/>
    <child link="left_spherical_wrist_2_link"/>
    <axis xyz="1. 0. 0."/>
    <limit lower="-2.2299999" upper="2.2299999" effort="9." velocity="1.2218"/>
  </joint>
  <joint name="left_joint_7" type="revolute">
    <origin xyz="-0.0001696 -0.10593 0. " rpy="0. 0. 1.5708035"/>
    <parent link="left_spherical_wrist_2_link"/>
    <child link="left_bracelet_link"/>
    <axis xyz="1. 0. 0."/>
    <limit lower="-5.9999991" upper="5.9999991" effort="9." velocity="1.2218"/>
  </joint>
  <joint name="left_kinova_joint_1" type="fixed">
    <origin xyz="0. 0. 0." rpy="0. 0. 0."/>
    <parent link="ewellix_lift_top_link"/>
    <child link="left_base_link"/>
  </joint>
  <joint name="left_tool_frame_joint" type="fixed">
    <origin xyz="-0.1199949 0. 0. " rpy="0.0000001 -0.0000001 -0.0000001"/>
    <parent link="left_end_effector_link"/>
    <child link="left_tool_frame"/>
  </joint>
  <joint name="right_arm_finger_joint" type="fixed">
    <origin xyz="0.0000001 0.0000002 -0.0000001" rpy="0.0006056 -0.0007268 0.000242 "/>
    <parent link="right_arm_robotiq_arg2f_base_link"/>
    <child link="right_arm_left_inner_knuckle"/>
  </joint>
  <joint name="right_arm_left_finger_joint" type="fixed">
    <origin xyz="0. 0. 0." rpy="0. 0. 0.0000002"/>
    <parent link="right_arm_left_inner_finger"/>
    <child link="right_arm_right_finger_mount"/>
  </joint>
  <joint name="right_arm_left_fingertip_fixed_joint" type="fixed">
    <origin xyz="0. 0. 0." rpy="0. 0. 0."/>
    <parent link="right_arm_left_finger_mount"/>
    <child link="right_arm_left_fingertip"/>
  </joint>
  <joint name="right_arm_left_inner_finger_joint" type="fixed">
    <origin xyz="0. 0. 0." rpy="0. 0. -0.0000002"/>
    <parent link="right_arm_left_outer_finger"/>
    <child link="right_arm_left_inner_finger"/>
  </joint>
  <joint name="right_arm_left_outer_finger_joint" type="fixed">
    <origin xyz="-0.0004806 1.2167337 -1.0672767" rpy="-0.0006057 0.0007267 -0.0002423"/>
    <parent link="right_arm_left_outer_knuckle"/>
    <child link="right_arm_left_outer_finger"/>
  </joint>
  <joint name="right_arm_left_outer_knuckle_joint" type="fixed">
    <origin xyz="0.0000001 0.0000002 -0.0000001" rpy="0.0006056 -0.0007268 0.000242 "/>
    <parent link="right_arm_robotiq_arg2f_base_link"/>
    <child link="right_arm_left_outer_knuckle"/>
  </joint>
  <joint name="right_arm_right_finger_joint" type="fixed">
    <origin xyz="0. 0. 0." rpy="0. 0. 0."/>
    <parent link="right_arm_right_inner_finger"/>
    <child link="right_arm_left_finger_mount"/>
  </joint>
  <joint name="right_arm_right_fingertip_fixed_joint" type="fixed">
    <origin xyz="0. 0.0000001 -0.0000001" rpy="0. 0. 0."/>
    <parent link="right_arm_right_finger_mount"/>
    <child link="right_arm_right_fingertip"/>
  </joint>
  <joint name="right_arm_right_inner_finger_joint" type="fixed">
    <origin xyz="0. 0. 0." rpy="0. 0. 0."/>
    <parent link="right_arm_right_outer_finger"/>
    <child link="right_arm_right_inner_finger"/>
  </joint>
  <joint name="right_arm_right_inner_knuckle_joint" type="fixed">
    <origin xyz="0.0000001 0.0000002 -0.0000001" rpy="0.0006056 -0.0007268 0.000242 "/>
    <parent link="right_arm_robotiq_arg2f_base_link"/>
    <child link="right_arm_right_inner_knuckle"/>
  </joint>
  <joint name="right_arm_right_outer_finger_joint" type="fixed">
    <origin xyz="-0.0004806 1.2167337 -1.0672767" rpy="-0.0006057 0.0007267 -0.0002426"/>
    <parent link="right_arm_right_outer_knuckle"/>
    <child link="right_arm_right_outer_finger"/>
  </joint>
  <joint name="right_arm_right_outer_knuckle_joint" type="fixed">
    <origin xyz="0.0000001 0.0000002 -0.0000001" rpy="0.0006056 -0.0007268 0.000242 "/>
    <parent link="right_arm_robotiq_arg2f_base_link"/>
    <child link="right_arm_right_outer_knuckle"/>
  </joint>
  <joint name="right_end_effector" type="fixed">
    <origin xyz="-0.0615251 0.0000051 0. " rpy="3.1415925 0. -0.0000037"/>
    <parent link="right_bracelet_link"/>
    <child link="right_end_effector_link"/>
  </joint>
  <joint name="right_gripper_base_joint" type="fixed">
    <origin xyz="0.000005 0. 0. " rpy="-1.5707964 -1.5707963 0. "/>
    <parent link="right_end_effector_link"/>
    <child link="right_arm_robotiq_arg2f_base_link"/>
  </joint>
  <joint name="right_joint_1" type="revolute">
    <origin xyz="0. -0.18643 0.17446" rpy="-1.5707964 -0.0000071 1.5707964"/>
    <parent link="right_base_link"/>
    <child link="right_shoulder_link"/>
    <axis xyz="1. 0. 0."/>
    <limit lower="-5.9999991" upper="5.9999991" effort="39." velocity="1.3963"/>
  </joint>
  <joint name="right_joint_2" type="revolute">
    <origin xyz="-0.12838 0.0053741 0. " rpy="0. 0. -1.5707927"/>
    <parent link="right_shoulder_link"/>
    <child link="right_half_arm_1_link"/>
    <axis xyz="1. 0. 0."/>
    <limit lower="-2.4099997" upper="2.4099997" effort="39." velocity="1.3963"/>
  </joint>
  <joint name="right_joint_3" type="revolute">
    <origin xyz="-0.0063792 -0.21038 0. " rpy="0. 0. 1.5708035"/>
    <parent link="right_half_arm_1_link"/>
    <child link="right_half_arm_2_link"/>
    <axis xyz="1. 0. 0."/>
    <limit lower="-5.9999991" upper="5.9999991" effort="39." velocity="1.3963"/>
  </joint>
  <joint name="right_joint_4" type="revolute">
    <origin xyz="-0.21038 0.0063708 0. " rpy="0. 0. -1.5708035"/>
    <parent link="right_half_arm_2_link"/>
    <child link="right_forearm_link"/>
    <axis xyz="1. 0. 0."/>
    <limit lower="-2.6599997" upper="2.6599997" effort="39." velocity="1.3963"/>
  </joint>
  <joint name="right_joint_5" type="revolute">
    <origin xyz="-0.0063793 -0.20843 0. " rpy="0. 0. 1.5708035"/>
    <parent link="right_forearm_link"/>
    <child link="right_spherical_wrist_1_link"/>
    <axis xyz="1. 0. 0."/>
    <limit lower="-5.9999991" upper="5.9999991" effort="9." velocity="1.2218"/>
  </joint>
  <joint name="right_joint_6" type="revolute">
    <origin xyz="-0.10593 0.0001804 0. " rpy="0. 0. -1.5708035"/>
    <parent link="right_spherical_wrist_1_link"/>
    <child link="right_spherical_wrist_2_link"/>
    <axis xyz="1. 0. 0."/>
    <limit lower="-2.2299999" upper="2.2299999" effort="9." velocity="1.2218"/>
  </joint>
  <joint name="right_joint_7" type="revolute">
    <origin xyz="-0.0001696 -0.10593 0. " rpy="0. 0. 1.5708035"/>
    <parent link="right_spherical_wrist_2_link"/>
    <child link="right_bracelet_link"/>
    <axis xyz="1. 0. 0."/>
    <limit lower="-5.9999991" upper="5.9999991" effort="9." velocity="1.2218"/>
  </joint>
  <joint name="right_kinova_joint_1" type="fixed">
    <origin xyz="0. 0. 0." rpy="0.0000001 0. 0. "/>
    <parent link="ewellix_lift_top_link"/>
    <child link="right_base_link"/>
  </joint>
  <joint name="right_tool_frame_joint" type="fixed">
    <origin xyz="-0.1199949 0. 0. " rpy="3.14 0. 0. "/>
    <parent link="right_end_effector_link"/>
    <child link="right_tool_frame"/>
  </joint>
  <joint name="root_joint" type="fixed">
    <origin xyz="0. 0. 0." rpy="0. 0. 0."/>
    <parent link="World"/>
    <child link="base_link"/>
  </joint>
  <link name="World"/>
  <link name="base_link">
    <visual>
      <origin xyz="0. 0. 0." rpy="0. 0. 0."/>
      <geometry>
        <mesh filename="meshes/base_link_visuals_mesh_0.obj" scale="1. 1. 1."/>
      </geometry>
    </visual>
    <visual>
      <origin xyz="0. 0. 0." rpy="0. 0. 0."/>
      <geometry>
        <mesh filename="meshes/base_link_visuals_mesh_1.obj" scale="1. 1. 1."/>
      </geometry>
    </visual>
    <visual>
      <origin xyz="0. 0. 0.28" rpy="0. 0. 1.5707964"/>
      <geometry>
        <mesh filename="meshes/base_link_visuals_mesh_2.obj" scale="0.001 0.001 0.001"/>
      </geometry>
    </visual>
    <visual>
      <origin xyz="0. 0. 0." rpy="0. 0. 0."/>
      <geometry>
        <mesh filename="meshes/base_link_collisions_mesh_0.obj" scale="1. 1. 1."/>
      </geometry>
    </visual>
    <visual>
      <origin xyz="0. 0. 0." rpy="0. 0. 0."/>
      <geometry>
        <mesh filename="meshes/base_link_collisions_mesh_1.obj" scale="1. 1. 1."/>
      </geometry>
    </visual>
    <visual>
      <origin xyz="0. 0. 0.28" rpy="0. 0. 1.5707964"/>
      <geometry>
        <mesh filename="meshes/base_link_collisions_mesh_2.obj" scale="0.001 0.001 0.001"/>
      </geometry>
    </visual>
    <collision>
      <origin xyz="0. 0. 0." rpy="0. 0. 0."/>
      <geometry>
        <mesh filename="meshes/base_link_collisions_mesh_0.obj" scale="1. 1. 1."/>
      </geometry>
    </collision>
    <collision>
      <origin xyz="0. 0. 0." rpy="0. 0. 0."/>
      <geometry>
        <mesh filename="meshes/base_link_collisions_mesh_1.obj" scale="1. 1. 1."/>
      </geometry>
    </collision>
    <collision>
      <origin xyz="0. 0. 0.28" rpy="0. 0. 1.5707964"/>
      <geometry>
        <mesh filename="meshes/base_link_collisions_mesh_2.obj" scale="0.001 0.001 0.001"/>
      </geometry>
    </collision>
  </link>
  <link name="ewellix_lift_top_link">
    <inertial>
      <origin xyz="0. 0. 0." rpy="0. 0. 0."/>
      <mass value="2."/>
      <inertia ixx="0." ixy="0." ixz="0." iyy="0." iyz="0." izz="0."/>
    </inertial>
    <visual>
      <origin xyz="0. 0. 0." rpy="0. 0. -1.5707964"/>
      <geometry>
        <mesh filename="meshes/ewellix_lift_top_link_collisions.obj" scale="0.001 0.001 0.001"/>
      </geometry>
    </visual>
    <visual>
      <origin xyz="0. 0. 0." rpy="0. 0. -1.5707964"/>
      <geometry>
        <mesh filename="meshes/ewellix_lift_top_link_visuals_mesh_0.obj" scale="0.001 0.001 0.001"/>
      </geometry>
    </visual>
    <visual>
      <origin xyz="0. 0. 0." rpy="0. 0. 0."/>
      <geometry>
        <mesh filename="meshes/ewellix_lift_top_link_visuals_mesh_1.obj" scale="1. 1. 1."/>
      </geometry>
    </visual>
    <visual>
      <origin xyz="0. 0. 0." rpy="0. 0. -1.5707964"/>
      <geometry>
        <mesh filename="meshes/ewellix_lift_top_link_visuals_mesh_2.obj" scale="0.001 0.001 0.001"/>
      </geometry>
    </visual>
    <collision>
      <origin xyz="0. 0. 0." rpy="0. 0. -1.5707964"/>
      <geometry>
        <mesh filename="meshes/ewellix_lift_top_link_collisions.obj" scale="0.001 0.001 0.001"/>
      </geometry>
    </collision>
  </link>
  <link name="left_arm_left_finger_mount">
    <inertial>
      <origin xyz="0. 0. 0." rpy="0. 0. 0."/>
      <mass value="0.01"/>
      <inertia ixx="0." ixy="0." ixz="0." iyy="0." iyz="0." izz="0."/>
    </inertial>
    <visual>
      <origin xyz="-0.0012346 0.0057354 -0.000109 " rpy="0. 0. 0."/>
      <geometry>
        <mesh filename="meshes/left_arm_left_finger_mount_collisions.obj" scale="1. 1. 1."/>
      </geometry>
    </visual>
    <visual>
      <origin xyz="-0.0012346 0.0057354 -0.000109 " rpy="0. 0. 0."/>
      <geometry>
        <mesh filename="meshes/left_arm_left_finger_mount_visuals_mesh_0.obj" scale="1. 1. 1."/>
      </geometry>
    </visual>
    <visual>
      <origin xyz="-0.0012346 0.0057354 -0.000109 " rpy="0. 0. 0."/>
      <geometry>
        <mesh filename="meshes/left_arm_left_finger_mount_visuals_mesh_1.obj" scale="1. 1. 1."/>
      </geometry>
    </visual>
    <collision>
      <origin xyz="-0.0012346 0.0057354 -0.000109 " rpy="0. 0. 0."/>
      <geometry>
        <mesh filename="meshes/left_arm_left_finger_mount_collisions.obj" scale="1. 1. 1."/>
      </geometry>
    </collision>
  </link>
  <link name="left_arm_left_fingertip">
    <inertial>
      <origin xyz="0. 0. 0." rpy="0. 0. 0."/>
      <mass value="0.01"/>
      <inertia ixx="0." ixy="0." ixz="0." iyy="0." iyz="0." izz="0."/>
    </inertial>
    <visual>
      <origin xyz="0. 0. 0." rpy="0. 0. 0."/>
      <geometry>
        <mesh filename="meshes/left_arm_left_fingertip_visuals.obj" scale="1. 1. 1."/>
      </geometry>
    </visual>
    <visual>
      <origin xyz="0. 0. 0." rpy="0. 0. 0."/>
      <geometry>
        <mesh filename="meshes/left_arm_left_fingertip_collisions.obj" scale="1. 1. 1."/>
      </geometry>
    </visual>
    <collision>
      <origin xyz="0. 0. 0." rpy="0. 0. 0."/>
      <geometry>
        <mesh filename="meshes/left_arm_left_fingertip_collisions.obj" scale="1. 1. 1."/>
      </geometry>
    </collision>
  </link>
  <link name="left_arm_left_inner_finger">
    <inertial>
      <origin xyz="0. 0. 0." rpy="0. 0. 0."/>
      <mass value="0.0104003"/>
      <inertia ixx="0." ixy="0." ixz="0." iyy="0." iyz="0." izz="0."/>
    </inertial>
    <visual>
      <origin xyz="-0.0004 -0.01207 0.00733" rpy="-1.5707614 -0.0001222 1.5707963"/>
      <geometry>
        <mesh filename="meshes/left_arm_left_inner_finger_collisions.obj" scale="1. 1. 1."/>
      </geometry>
    </visual>
    <visual>
      <origin xyz="-0.0003999 -0.012069 0.0073263" rpy="1.5708312 -0.0254294 -1.5707964"/>
      <geometry>
        <mesh filename="meshes/left_arm_left_inner_finger_visuals_mesh_0.obj" scale="1. 1. 1."/>
      </geometry>
    </visual>
    <visual>
      <origin xyz="-0.0004 -0.01207 0.00733" rpy="-1.5707614 -0.0001222 1.5707963"/>
      <geometry>
        <mesh filename="meshes/left_arm_left_inner_finger_visuals_mesh_1.obj" scale="1. 1. 1."/>
      </geometry>
    </visual>
    <collision>
      <origin xyz="-0.0004 -0.01207 0.00733" rpy="-1.5707614 -0.0001222 1.5707963"/>
      <geometry>
        <mesh filename="meshes/left_arm_left_inner_finger_collisions.obj" scale="1. 1. 1."/>
      </geometry>
    </collision>
  </link>
  <link name="left_arm_left_inner_knuckle">
    <inertial>
      <origin xyz="0. 0. 0." rpy="0. 0. 0."/>
      <mass value="0.0271177"/>
      <inertia ixx="0." ixy="0." ixz="0." iyy="0." iyz="0." izz="0."/>
    </inertial>
    <visual>
      <origin xyz="0.0000003 -0.0127634 0.0614192" rpy="0. 0. 3.1415925"/>
      <geometry>
        <mesh filename="meshes/left_arm_left_inner_knuckle_collisions.obj" scale="0.001 0.001 0.001"/>
      </geometry>
    </visual>
    <visual>
      <origin xyz="0.0000003 -0.0127634 0.0614192" rpy="0. 0. 3.1415925"/>
      <geometry>
        <mesh filename="meshes/left_arm_left_inner_knuckle_visuals_mesh_0.obj" scale="0.001 0.001 0.001"/>
      </geometry>
    </visual>
    <visual>
      <origin xyz="0.0000003 -0.0127634 0.0614192" rpy="0. 0. 3.1415925"/>
      <geometry>
        <mesh filename="meshes/left_arm_left_inner_knuckle_visuals_mesh_1.obj" scale="0.001 0.001 0.001"/>
      </geometry>
    </visual>
    <collision>
      <origin xyz="0.0000003 -0.0127634 0.0614192" rpy="0. 0. 3.1415925"/>
      <geometry>
        <mesh filename="meshes/left_arm_left_inner_knuckle_collisions.obj" scale="0.001 0.001 0.001"/>
      </geometry>
    </collision>
  </link>
  <link name="left_arm_left_outer_finger">
    <inertial>
      <origin xyz="0. 0. 0." rpy="0. 0. 0."/>
      <mass value="0.0226142"/>
      <inertia ixx="0." ixy="0." ixz="0." iyy="0." iyz="0." izz="0."/>
    </inertial>
    <visual>
      <origin xyz="0.0000019 0. 0. " rpy="0. 0. 0."/>
      <geometry>
        <mesh filename="meshes/left_arm_left_outer_finger_collisions.obj" scale="0.001 0.001 0.001"/>
      </geometry>
    </visual>
    <visual>
      <origin xyz="0.0000019 0. 0. " rpy="0. 0. 0."/>
      <geometry>
        <mesh filename="meshes/left_arm_left_outer_finger_visuals_mesh_0.obj" scale="0.001 0.001 0.001"/>
      </geometry>
    </visual>
    <visual>
      <origin xyz="0.0000019 0. 0. " rpy="0. 0. 0."/>
      <geometry>
        <mesh filename="meshes/left_arm_left_outer_finger_visuals_mesh_1.obj" scale="0.001 0.001 0.001"/>
      </geometry>
    </visual>
    <collision>
      <origin xyz="0.0000019 0. 0. " rpy="0. 0. 0."/>
      <geometry>
        <mesh filename="meshes/left_arm_left_outer_finger_collisions.obj" scale="0.001 0.001 0.001"/>
      </geometry>
    </collision>
  </link>
  <link name="left_arm_left_outer_knuckle">
    <inertial>
      <origin xyz="0. 0. 0." rpy="0. 0. 0."/>
      <mass value="0.008532"/>
      <inertia ixx="0." ixy="0." ixz="0." iyy="0." iyz="0." izz="0."/>
    </inertial>
    <visual>
      <origin xyz="0.0000046 -0.0306011 0.05491 " rpy="0. 0. 3.1415055"/>
      <geometry>
        <mesh filename="meshes/left_arm_left_outer_knuckle_collisions.obj" scale="0.001 0.001 0.001"/>
      </geometry>
    </visual>
    <visual>
      <origin xyz="0.0000046 -0.0306011 0.05491 " rpy="0. 0. 3.1415055"/>
      <geometry>
        <mesh filename="meshes/left_arm_left_outer_knuckle_visuals_mesh_0.obj" scale="0.001 0.001 0.001"/>
      </geometry>
    </visual>
    <visual>
      <origin xyz="0.0000046 -0.0306011 0.05491 " rpy="0. 0. 3.1415055"/>
      <geometry>
        <mesh filename="meshes/left_arm_left_outer_knuckle_visuals_mesh_1.obj" scale="0.001 0.001 0.001"/>
      </geometry>
    </visual>
    <collision>
      <origin xyz="0.0000046 -0.0306011 0.05491 " rpy="0. 0. 3.1415055"/>
      <geometry>
        <mesh filename="meshes/left_arm_left_outer_knuckle_collisions.obj" scale="0.001 0.001 0.001"/>
      </geometry>
    </collision>
  </link>
  <link name="left_arm_right_finger_mount">
    <inertial>
      <origin xyz="0. 0. 0." rpy="0. 0. 0."/>
      <mass value="0.01"/>
      <inertia ixx="0." ixy="0." ixz="0." iyy="0." iyz="0." izz="0."/>
    </inertial>
    <visual>
      <origin xyz="-0.0012346 0.0057354 -0.000109 " rpy="0. 0. 0."/>
      <geometry>
        <mesh filename="meshes/left_arm_right_finger_mount_collisions.obj" scale="1. 1. 1."/>
      </geometry>
    </visual>
    <visual>
      <origin xyz="-0.0012346 0.0057354 -0.000109 " rpy="0. 0. 0."/>
      <geometry>
        <mesh filename="meshes/left_arm_right_finger_mount_visuals_mesh_0.obj" scale="1. 1. 1."/>
      </geometry>
    </visual>
    <visual>
      <origin xyz="-0.0012346 0.0057354 -0.000109 " rpy="0. 0. 0."/>
      <geometry>
        <mesh filename="meshes/left_arm_right_finger_mount_visuals_mesh_1.obj" scale="1. 1. 1."/>
      </geometry>
    </visual>
    <collision>
      <origin xyz="-0.0012346 0.0057354 -0.000109 " rpy="0. 0. 0."/>
      <geometry>
        <mesh filename="meshes/left_arm_right_finger_mount_collisions.obj" scale="1. 1. 1."/>
      </geometry>
    </collision>
  </link>
  <link name="left_arm_right_fingertip">
    <inertial>
      <origin xyz="0. 0. 0." rpy="0. 0. 0."/>
      <mass value="0.01"/>
      <inertia ixx="0." ixy="0." ixz="0." iyy="0." iyz="0." izz="0."/>
    </inertial>
    <visual>
      <origin xyz="0. 0. 0." rpy="0. 0. 0."/>
      <geometry>
        <mesh filename="meshes/left_arm_right_fingertip_visuals.obj" scale="1. 1. 1."/>
      </geometry>
    </visual>
    <visual>
      <origin xyz="0. 0. 0." rpy="0. 0. 0."/>
      <geometry>
        <mesh filename="meshes/left_arm_right_fingertip_collisions.obj" scale="1. 1. 1."/>
      </geometry>
    </visual>
    <collision>
      <origin xyz="0. 0. 0." rpy="0. 0. 0."/>
      <geometry>
        <mesh filename="meshes/left_arm_right_fingertip_collisions.obj" scale="1. 1. 1."/>
      </geometry>
    </collision>
  </link>
  <link name="left_arm_right_inner_finger">
    <inertial>
      <origin xyz="0. 0. 0." rpy="0. 0. 0."/>
      <mass value="0.0104003"/>
      <inertia ixx="0." ixy="0." ixz="0." iyy="0." iyz="0." izz="0."/>
    </inertial>
    <visual>
      <origin xyz="-0.0004045 0.0434311 0.04382 " rpy="-1.5707614 -0.0001222 1.5707963"/>
      <geometry>
        <mesh filename="meshes/left_arm_right_inner_finger_collisions.obj" scale="1. 1. 1."/>
      </geometry>
    </visual>
    <visual>
      <origin xyz="-0.0004045 0.0434321 0.0438163" rpy="1.5708313 -0.0254294 -1.5707964"/>
      <geometry>
        <mesh filename="meshes/left_arm_right_inner_finger_visuals_mesh_0.obj" scale="1. 1. 1."/>
      </geometry>
    </visual>
    <visual>
      <origin xyz="-0.0004045 0.0434311 0.04382 " rpy="-1.5707614 -0.0001222 1.5707963"/>
      <geometry>
        <mesh filename="meshes/left_arm_right_inner_finger_visuals_mesh_1.obj" scale="1. 1. 1."/>
      </geometry>
    </visual>
    <collision>
      <origin xyz="-0.0004045 0.0434311 0.04382 " rpy="-1.5707614 -0.0001222 1.5707963"/>
      <geometry>
        <mesh filename="meshes/left_arm_right_inner_finger_collisions.obj" scale="1. 1. 1."/>
      </geometry>
    </collision>
  </link>
  <link name="left_arm_right_inner_knuckle">
    <inertial>
      <origin xyz="0. 0. 0." rpy="0. 0. 0."/>
      <mass value="0.0271177"/>
      <inertia ixx="0." ixy="0." ixz="0." iyy="0." iyz="0." izz="0."/>
    </inertial>
    <visual>
      <origin xyz="-0.0000001 0.0127 0.06142 " rpy="0. 0. 0."/>
      <geometry>
        <mesh filename="meshes/left_arm_right_inner_knuckle_collisions.obj" scale="0.001 0.001 0.001"/>
      </geometry>
    </visual>
    <visual>
      <origin xyz="-0.0000001 0.0127 0.06142 " rpy="0. 0. 0."/>
      <geometry>
        <mesh filename="meshes/left_arm_right_inner_knuckle_visuals_mesh_0.obj" scale="0.001 0.001 0.001"/>
      </geometry>
    </visual>
    <visual>
      <origin xyz="-0.0000001 0.0127 0.06142 " rpy="0. 0. 0."/>
      <geometry>
        <mesh filename="meshes/left_arm_right_inner_knuckle_visuals_mesh_1.obj" scale="0.001 0.001 0.001"/>
      </geometry>
    </visual>
    <collision>
      <origin xyz="-0.0000001 0.0127 0.06142 " rpy="0. 0. 0."/>
      <geometry>
        <mesh filename="meshes/left_arm_right_inner_knuckle_collisions.obj" scale="0.001 0.001 0.001"/>
      </geometry>
    </collision>
  </link>
  <link name="left_arm_right_outer_finger">
    <inertial>
      <origin xyz="0. 0. 0." rpy="0. 0. 0."/>
      <mass value="0.0226142"/>
      <inertia ixx="0." ixy="0." ixz="0." iyy="0." iyz="0." izz="0."/>
    </inertial>
    <visual>
      <origin xyz="0.0000047 0. 0. " rpy="0. 0. 0."/>
      <geometry>
        <mesh filename="meshes/left_arm_right_outer_finger_collisions.obj" scale="0.001 0.001 0.001"/>
      </geometry>
    </visual>
    <visual>
      <origin xyz="0.0000047 0. 0. " rpy="0. 0. 0."/>
      <geometry>
        <mesh filename="meshes/left_arm_right_outer_finger_visuals_mesh_0.obj" scale="0.001 0.001 0.001"/>
      </geometry>
    </visual>
    <visual>
      <origin xyz="0.0000047 0. 0. " rpy="0. 0. 0."/>
      <geometry>
        <mesh filename="meshes/left_arm_right_outer_finger_visuals_mesh_1.obj" scale="0.001 0.001 0.001"/>
      </geometry>
    </visual>
    <collision>
      <origin xyz="0.0000047 0. 0. " rpy="0. 0. 0."/>
      <geometry>
        <mesh filename="meshes/left_arm_right_outer_finger_collisions.obj" scale="0.001 0.001 0.001"/>
      </geometry>
    </collision>
  </link>
  <link name="left_arm_right_outer_knuckle">
    <inertial>
      <origin xyz="0. 0. 0." rpy="0. 0. 0."/>
      <mass value="0.008532"/>
      <inertia ixx="0." ixy="0." ixz="0." iyy="0." iyz="0." izz="0."/>
    </inertial>
    <visual>
      <origin xyz="-0.0000045 0.0306011 0.05491 " rpy="0. 0. 0."/>
      <geometry>
        <mesh filename="meshes/left_arm_right_outer_knuckle_collisions.obj" scale="0.001 0.001 0.001"/>
      </geometry>
    </visual>
    <visual>
      <origin xyz="-0.0000045 0.0306011 0.05491 " rpy="0. 0. 0."/>
      <geometry>
        <mesh filename="meshes/left_arm_right_outer_knuckle_visuals_mesh_0.obj" scale="0.001 0.001 0.001"/>
      </geometry>
    </visual>
    <visual>
      <origin xyz="-0.0000045 0.0306011 0.05491 " rpy="0. 0. 0."/>
      <geometry>
        <mesh filename="meshes/left_arm_right_outer_knuckle_visuals_mesh_1.obj" scale="0.001 0.001 0.001"/>
      </geometry>
    </visual>
    <collision>
      <origin xyz="-0.0000045 0.0306011 0.05491 " rpy="0. 0. 0."/>
      <geometry>
        <mesh filename="meshes/left_arm_right_outer_knuckle_collisions.obj" scale="0.001 0.001 0.001"/>
      </geometry>
    </collision>
  </link>
  <link name="left_arm_robotiq_arg2f_base_link">
    <inertial>
      <origin xyz="0. 0. 0." rpy="0. 0. 0."/>
      <mass value="0.22652"/>
      <inertia ixx="0." ixy="0." ixz="0." iyy="0." iyz="0." izz="0."/>
    </inertial>
    <visual>
      <origin xyz="0. 0. 0." rpy="0. 0. 0."/>
      <geometry>
        <mesh filename="meshes/left_arm_robotiq_arg2f_base_link_collisions.obj" scale="1. 1. 1."/>
      </geometry>
    </visual>
    <visual>
      <origin xyz="0. 0. 0." rpy="0. 0. 0."/>
      <geometry>
        <mesh filename="meshes/left_arm_robotiq_arg2f_base_link_visuals_mesh_0.obj" scale="1. 1. 1."/>
      </geometry>
    </visual>
    <visual>
      <origin xyz="0. 0. 0." rpy="0. 0. 0."/>
      <geometry>
        <mesh filename="meshes/left_arm_robotiq_arg2f_base_link_visuals_mesh_1.obj" scale="1. 1. 1."/>
      </geometry>
    </visual>
    <collision>
      <origin xyz="0. 0. 0." rpy="0. 0. 0."/>
      <geometry>
        <mesh filename="meshes/left_arm_robotiq_arg2f_base_link_collisions.obj" scale="1. 1. 1."/>
      </geometry>
    </collision>
  </link>
  <link name="left_base_link">
    <inertial>
      <origin xyz="0. 0. 0." rpy="0. 0. 0."/>
      <mass value="1.697"/>
      <inertia ixx="0." ixy="0." ixz="0." iyy="0." iyz="0." izz="0."/>
    </inertial>
    <visual>
      <origin xyz="0. 0.03 0.17446" rpy="-1.5707964 0. 0. "/>
      <geometry>
        <mesh filename="meshes/left_base_link_collisions.obj" scale="1. 1. 1."/>
      </geometry>
    </visual>
    <visual>
      <origin xyz="0. 0.03 0.17446" rpy="-1.5707964 0. 0. "/>
      <geometry>
        <mesh filename="meshes/left_base_link_visuals_mesh_0.obj" scale="1. 1. 1."/>
      </geometry>
    </visual>
    <visual>
      <origin xyz="0. 0.03 0.17446" rpy="-1.5707964 0. 0. "/>
      <geometry>
        <mesh filename="meshes/left_base_link_visuals_mesh_1.obj" scale="1. 1. 1."/>
      </geometry>
    </visual>
    <collision>
      <origin xyz="0. 0.03 0.17446" rpy="-1.5707964 0. 0. "/>
      <geometry>
        <mesh filename="meshes/left_base_link_collisions.obj" scale="1. 1. 1."/>
      </geometry>
    </collision>
  </link>
  <link name="left_bracelet_link">
    <inertial>
      <origin xyz="0. 0. 0." rpy="0. 0. 0."/>
      <mass value="0.5"/>
      <inertia ixx="0." ixy="0." ixz="0." iyy="0." iyz="0." izz="0."/>
    </inertial>
    <visual>
      <origin xyz="-0.0000001 0.000005 0. " rpy="0.0000036 1.5707963 0. "/>
      <geometry>
        <mesh filename="meshes/left_bracelet_link_collisions.obj" scale="1. 1. 1."/>
      </geometry>
    </visual>
    <visual>
      <origin xyz="-0.0000001 0.000005 0. " rpy="0.0000036 1.5707963 0. "/>
      <geometry>
        <mesh filename="meshes/left_bracelet_link_visuals_mesh_0.obj" scale="1. 1. 1."/>
      </geometry>
    </visual>
    <visual>
      <origin xyz="-0.0000001 0.000005 0. " rpy="0.0000036 1.5707963 0. "/>
      <geometry>
        <mesh filename="meshes/left_bracelet_link_visuals_mesh_1.obj" scale="1. 1. 1."/>
      </geometry>
    </visual>
    <collision>
      <origin xyz="-0.0000001 0.000005 0. " rpy="0.0000036 1.5707963 0. "/>
      <geometry>
        <mesh filename="meshes/left_bracelet_link_collisions.obj" scale="1. 1. 1."/>
      </geometry>
    </collision>
  </link>
  <link name="left_end_effector_link">
    <inertial>
      <origin xyz="0. 0. 0." rpy="0. 0. 0."/>
      <mass value="0.000001"/>
      <inertia ixx="0." ixy="0." ixz="0." iyy="0." iyz="0." izz="0."/>
    </inertial>
  </link>
  <link name="left_forearm_link">
    <inertial>
      <origin xyz="0. 0. 0." rpy="0. 0. 0."/>
      <mass value="0.9302"/>
      <inertia ixx="0." ixy="0." ixz="0." iyy="0." iyz="0." izz="0."/>
    </inertial>
    <visual>
      <origin xyz="-0.0000051 0. 0. " rpy="-0.0307582 1.5696613 -0.0307546"/>
      <geometry>
        <mesh filename="meshes/left_forearm_link_collisions.obj" scale="1. 1. 1."/>
      </geometry>
    </visual>
    <visual>
      <origin xyz="-0.0000051 0. 0. " rpy="-0.0307582 1.5696613 -0.0307546"/>
      <geometry>
        <mesh filename="meshes/left_forearm_link_visuals_mesh_0.obj" scale="1. 1. 1."/>
      </geometry>
    </visual>
    <visual>
      <origin xyz="-0.0000051 0. 0. " rpy="-0.0307582 1.5696613 -0.0307546"/>
      <geometry>
        <mesh filename="meshes/left_forearm_link_visuals_mesh_1.obj" scale="1. 1. 1."/>
      </geometry>
    </visual>
    <collision>
      <origin xyz="-0.0000051 0. 0. " rpy="-0.0307582 1.5696613 -0.0307546"/>
      <geometry>
        <mesh filename="meshes/left_forearm_link_collisions.obj" scale="1. 1. 1."/>
      </geometry>
    </collision>
  </link>
  <link name="left_half_arm_1_link">
    <inertial>
      <origin xyz="0. 0. 0." rpy="0. 0. 0."/>
      <mass value="1.1636"/>
      <inertia ixx="0." ixy="0." ixz="0." iyy="0." iyz="0." izz="0."/>
    </inertial>
    <visual>
      <origin xyz="-0.000005 0. 0. " rpy="-0.0000036 1.5707963 0. "/>
      <geometry>
        <mesh filename="meshes/left_half_arm_1_link_collisions.obj" scale="1. 1. 1."/>
      </geometry>
    </visual>
    <visual>
      <origin xyz="-0.000005 0. 0. " rpy="-0.0000036 1.5707963 0. "/>
      <geometry>
        <mesh filename="meshes/left_half_arm_1_link_visuals_mesh_0.obj" scale="1. 1. 1."/>
      </geometry>
    </visual>
    <visual>
      <origin xyz="-0.000005 0. 0. " rpy="-0.0000036 1.5707963 0. "/>
      <geometry>
        <mesh filename="meshes/left_half_arm_1_link_visuals_mesh_1.obj" scale="1. 1. 1."/>
      </geometry>
    </visual>
    <collision>
      <origin xyz="-0.000005 0. 0. " rpy="-0.0000036 1.5707963 0. "/>
      <geometry>
        <mesh filename="meshes/left_half_arm_1_link_collisions.obj" scale="1. 1. 1."/>
      </geometry>
    </collision>
  </link>
  <link name="left_half_arm_2_link">
    <inertial>
      <origin xyz="0. 0. 0." rpy="0. 0. 0."/>
      <mass value="1.1636"/>
      <inertia ixx="0." ixy="0." ixz="0." iyy="0." iyz="0." izz="0."/>
    </inertial>
    <visual>
      <origin xyz="0. -0.000005 0. " rpy="0.0000036 1.5707963 0. "/>
      <geometry>
        <mesh filename="meshes/left_half_arm_2_link_collisions.obj" scale="1. 1. 1."/>
      </geometry>
    </visual>
    <visual>
      <origin xyz="0. -0.000005 0. " rpy="0.0000036 1.5707963 0. "/>
      <geometry>
        <mesh filename="meshes/left_half_arm_2_link_visuals_mesh_0.obj" scale="1. 1. 1."/>
      </geometry>
    </visual>
    <visual>
      <origin xyz="0. -0.000005 0. " rpy="0.0000036 1.5707963 0. "/>
      <geometry>
        <mesh filename="meshes/left_half_arm_2_link_visuals_mesh_1.obj" scale="1. 1. 1."/>
      </geometry>
    </visual>
    <collision>
      <origin xyz="0. -0.000005 0. " rpy="0.0000036 1.5707963 0. "/>
      <geometry>
        <mesh filename="meshes/left_half_arm_2_link_collisions.obj" scale="1. 1. 1."/>
      </geometry>
    </collision>
  </link>
  <link name="left_shoulder_link">
    <inertial>
      <origin xyz="0. 0. 0." rpy="0. 0. 0."/>
      <mass value="1.3773"/>
      <inertia ixx="0." ixy="0." ixz="0." iyy="0." iyz="0." izz="0."/>
    </inertial>
    <visual>
      <origin xyz="0. 0. 0." rpy="-0.000006 1.5707963 0.0000012"/>
      <geometry>
        <mesh filename="meshes/left_shoulder_link_collisions.obj" scale="1. 1. 1."/>
      </geometry>
    </visual>
    <visual>
      <origin xyz="0. 0. 0." rpy="-0.000006 1.5707963 0.0000012"/>
      <geometry>
        <mesh filename="meshes/left_shoulder_link_visuals_mesh_0.obj" scale="1. 1. 1."/>
      </geometry>
    </visual>
    <visual>
      <origin xyz="0. 0. 0." rpy="-0.000006 1.5707963 0.0000012"/>
      <geometry>
        <mesh filename="meshes/left_shoulder_link_visuals_mesh_1.obj" scale="1. 1. 1."/>
      </geometry>
    </visual>
    <collision>
      <origin xyz="0. 0. 0." rpy="-0.000006 1.5707963 0.0000012"/>
      <geometry>
        <mesh filename="meshes/left_shoulder_link_collisions.obj" scale="1. 1. 1."/>
      </geometry>
    </collision>
  </link>
  <link name="left_spherical_wrist_1_link">
    <inertial>
      <origin xyz="0. 0. 0." rpy="0. 0. 0."/>
      <mass value="0.6781"/>
      <inertia ixx="0." ixy="0." ixz="0." iyy="0." iyz="0." izz="0."/>
    </inertial>
    <visual>
      <origin xyz="0. 0.000005 0. " rpy="1.5400866 1.5696615 1.5400832"/>
      <geometry>
        <mesh filename="meshes/left_spherical_wrist_1_link_collisions.obj" scale="1. 1. 1."/>
      </geometry>
    </visual>
    <visual>
      <origin xyz="0. 0.000005 0. " rpy="1.5400866 1.5696615 1.5400832"/>
      <geometry>
        <mesh filename="meshes/left_spherical_wrist_1_link_visuals_mesh_0.obj" scale="1. 1. 1."/>
      </geometry>
    </visual>
    <visual>
      <origin xyz="0. 0.000005 0. " rpy="1.5400866 1.5696615 1.5400832"/>
      <geometry>
        <mesh filename="meshes/left_spherical_wrist_1_link_visuals_mesh_1.obj" scale="1. 1. 1."/>
      </geometry>
    </visual>
    <collision>
      <origin xyz="0. 0.000005 0. " rpy="1.5400866 1.5696615 1.5400832"/>
      <geometry>
        <mesh filename="meshes/left_spherical_wrist_1_link_collisions.obj" scale="1. 1. 1."/>
      </geometry>
    </collision>
  </link>
  <link name="left_spherical_wrist_2_link">
    <inertial>
      <origin xyz="0. 0. 0." rpy="0. 0. 0."/>
      <mass value="0.6781"/>
      <inertia ixx="0." ixy="0." ixz="0." iyy="0." iyz="0." izz="0."/>
    </inertial>
    <visual>
      <origin xyz="0.000005 0. 0. " rpy="-0.0000036 1.5707963 0. "/>
      <geometry>
        <mesh filename="meshes/left_spherical_wrist_2_link_collisions.obj" scale="1. 1. 1."/>
      </geometry>
    </visual>
    <visual>
      <origin xyz="0.000005 0. 0. " rpy="-0.0000036 1.5707963 0. "/>
      <geometry>
        <mesh filename="meshes/left_spherical_wrist_2_link_visuals_mesh_0.obj" scale="1. 1. 1."/>
      </geometry>
    </visual>
    <visual>
      <origin xyz="0.000005 0. 0. " rpy="-0.0000036 1.5707963 0. "/>
      <geometry>
        <mesh filename="meshes/left_spherical_wrist_2_link_visuals_mesh_1.obj" scale="1. 1. 1."/>
      </geometry>
    </visual>
    <collision>
      <origin xyz="0.000005 0. 0. " rpy="-0.0000036 1.5707963 0. "/>
      <geometry>
        <mesh filename="meshes/left_spherical_wrist_2_link_collisions.obj" scale="1. 1. 1."/>
      </geometry>
    </collision>
  </link>
  <link name="left_tool_frame">
    <inertial>
      <origin xyz="0. 0. 0." rpy="0. 0. 0."/>
      <mass value="0.000001"/>
      <inertia ixx="0." ixy="0." ixz="0." iyy="0." iyz="0." izz="0."/>
    </inertial>
  </link>
  <link name="right_arm_left_finger_mount">
    <inertial>
      <origin xyz="0. 0. 0." rpy="0. 0. 0."/>
      <mass value="0.01"/>
      <inertia ixx="0." ixy="0." ixz="0." iyy="0." iyz="0." izz="0."/>
    </inertial>
    <visual>
      <origin xyz="0.0208691 -1.3685533 1.0576485" rpy="3.1415923 0.0000003 3.1415923"/>
      <geometry>
        <mesh filename="meshes/right_arm_left_finger_mount_collisions.obj" scale="1. 1. 1."/>
      </geometry>
    </visual>
    <visual>
      <origin xyz="0.0208691 -1.3685533 1.0576485" rpy="3.1415923 0.0000003 3.1415923"/>
      <geometry>
        <mesh filename="meshes/right_arm_left_finger_mount_visuals_mesh_0.obj" scale="1. 1. 1."/>
      </geometry>
    </visual>
    <visual>
      <origin xyz="0.0208691 -1.3685533 1.0576485" rpy="3.1415923 0.0000003 3.1415923"/>
      <geometry>
        <mesh filename="meshes/right_arm_left_finger_mount_visuals_mesh_1.obj" scale="1. 1. 1."/>
      </geometry>
    </visual>
    <visual>
      <origin xyz="0.0208691 -1.3685533 1.0576485" rpy="3.1415923 0.0000003 3.1415923"/>
      <geometry>
        <mesh filename="meshes/right_arm_left_finger_mount_visuals_mesh_2.obj" scale="1. 1. 1."/>
      </geometry>
    </visual>
    <visual>
      <origin xyz="0.0208691 -1.3685533 1.0576485" rpy="3.1415923 0.0000003 3.1415923"/>
      <geometry>
        <mesh filename="meshes/right_arm_left_finger_mount_visuals_mesh_3.obj" scale="1. 1. 1."/>
      </geometry>
    </visual>
    <collision>
      <origin xyz="0.0208691 -1.3685533 1.0576485" rpy="3.1415923 0.0000003 3.1415923"/>
      <geometry>
        <mesh filename="meshes/right_arm_left_finger_mount_collisions.obj" scale="1. 1. 1."/>
      </geometry>
    </collision>
  </link>
  <link name="right_arm_left_fingertip">
    <inertial>
      <origin xyz="0. 0. 0." rpy="0. 0. 0."/>
      <mass value="0.01"/>
      <inertia ixx="0." ixy="0." ixz="0." iyy="0." iyz="0." izz="0."/>
    </inertial>
    <visual>
      <origin xyz="0.0011909 -1.3570821 1.0446149" rpy="-1.570796 -0.0000003 -0.0000003"/>
      <geometry>
        <mesh filename="meshes/right_arm_left_fingertip_collisions.obj" scale="1. 1. 1."/>
      </geometry>
    </visual>
    <visual>
      <origin xyz="0.0011909 -1.3570821 1.0446149" rpy="-1.570796 -0.0000003 -0.0000003"/>
      <geometry>
        <mesh filename="meshes/right_arm_left_fingertip_visuals_mesh_0.obj" scale="1. 1. 1."/>
      </geometry>
    </visual>
    <visual>
      <origin xyz="0.0011909 -1.3570821 1.0446149" rpy="-1.570796 -0.0000003 -0.0000003"/>
      <geometry>
        <mesh filename="meshes/right_arm_left_fingertip_visuals_mesh_1.obj" scale="1. 1. 1."/>
      </geometry>
    </visual>
    <visual>
      <origin xyz="0.0011909 -1.3570821 1.0446149" rpy="-1.570796 -0.0000003 -0.0000003"/>
      <geometry>
        <mesh filename="meshes/right_arm_left_fingertip_visuals_mesh_2.obj" scale="1. 1. 1."/>
      </geometry>
    </visual>
    <collision>
      <origin xyz="0.0011909 -1.3570821 1.0446149" rpy="-1.570796 -0.0000003 -0.0000003"/>
      <geometry>
        <mesh filename="meshes/right_arm_left_fingertip_collisions.obj" scale="1. 1. 1."/>
      </geometry>
    </collision>
  </link>
  <link name="right_arm_left_inner_finger">
    <inertial>
      <origin xyz="0. 0. 0." rpy="0. 0. 0."/>
      <mass value="0.000001"/>
      <inertia ixx="0." ixy="0." ixz="0." iyy="0." iyz="0." izz="0."/>
    </inertial>
    <visual>
      <origin xyz="0.0451475 -1.2317853 1.066538 " rpy="3.141592 0.0000603 -0.0051406"/>
      <geometry>
        <mesh filename="meshes/right_arm_left_inner_finger_visuals.obj" scale="1. 1. 1."/>
      </geometry>
    </visual>
  </link>
  <link name="right_arm_left_inner_knuckle">
    <inertial>
      <origin xyz="0. 0. 0." rpy="0. 0. 0."/>
      <mass value="0.000001"/>
      <inertia ixx="0." ixy="0." ixz="0." iyy="0." iyz="0." izz="0."/>
    </inertial>
    <visual>
      <origin xyz="-0.0502405 -0.0110057 0.000045 " rpy="-3.1414127 0.0009804 0.8447831"/>
      <geometry>
        <mesh filename="meshes/right_arm_left_inner_knuckle_visuals.obj" scale="1. 1. 1."/>
      </geometry>
    </visual>
  </link>
  <link name="right_arm_left_outer_finger">
    <inertial>
      <origin xyz="0. 0. 0." rpy="0. 0. 0."/>
      <mass value="0.000001"/>
      <inertia ixx="0." ixy="0." ixz="0." iyy="0." iyz="0." izz="0."/>
    </inertial>
    <visual>
      <origin xyz="-0.0513745 -1.2127253 1.0665418" rpy="-3.141554 0.000045 0.8452485"/>
      <geometry>
        <mesh filename="meshes/right_arm_left_outer_finger_visuals.obj" scale="1. 1. 1."/>
      </geometry>
    </visual>
  </link>
  <link name="right_arm_left_outer_knuckle">
    <inertial>
      <origin xyz="0. 0. 0." rpy="0. 0. 0."/>
      <mass value="0.000001"/>
      <inertia ixx="0." ixy="0." ixz="0." iyy="0." iyz="0." izz="0."/>
    </inertial>
    <visual>
      <origin xyz="-0.0514058 0.0046692 -0.0001254" rpy="3.0996704 -0.0893324 0.8473942"/>
      <geometry>
        <mesh filename="meshes/right_arm_left_outer_knuckle_visuals.obj" scale="1. 1. 1."/>
      </geometry>
    </visual>
  </link>
  <link name="right_arm_right_finger_mount">
    <inertial>
      <origin xyz="0. 0. 0." rpy="0. 0. 0."/>
      <mass value="0.01"/>
      <inertia ixx="0." ixy="0." ixz="0." iyy="0." iyz="0." izz="0."/>
    </inertial>
    <visual>
      <origin xyz="-0.0212918 -1.3652896 1.0550044" rpy="0. 0. 0."/>
      <geometry>
        <mesh filename="meshes/right_arm_right_finger_mount_collisions.obj" scale="1. 1. 1."/>
      </geometry>
    </visual>
    <visual>
      <origin xyz="-0.0212918 -1.3652896 1.0550044" rpy="0. 0. 0."/>
      <geometry>
        <mesh filename="meshes/right_arm_right_finger_mount_visuals_mesh_0.obj" scale="1. 1. 1."/>
      </geometry>
    </visual>
    <visual>
      <origin xyz="-0.0212918 -1.3652896 1.0550044" rpy="0. 0. 0."/>
      <geometry>
        <mesh filename="meshes/right_arm_right_finger_mount_visuals_mesh_1.obj" scale="1. 1. 1."/>
      </geometry>
    </visual>
    <visual>
      <origin xyz="-0.0212918 -1.3652896 1.0550044" rpy="0. 0. 0."/>
      <geometry>
        <mesh filename="meshes/right_arm_right_finger_mount_visuals_mesh_2.obj" scale="1. 1. 1."/>
      </geometry>
    </visual>
    <visual>
      <origin xyz="-0.0212918 -1.3652896 1.0550044" rpy="0. 0. 0."/>
      <geometry>
        <mesh filename="meshes/right_arm_right_finger_mount_visuals_mesh_3.obj" scale="1. 1. 1."/>
      </geometry>
    </visual>
    <collision>
      <origin xyz="-0.0212918 -1.3652896 1.0550044" rpy="0. 0. 0."/>
      <geometry>
        <mesh filename="meshes/right_arm_right_finger_mount_collisions.obj" scale="1. 1. 1."/>
      </geometry>
    </collision>
  </link>
  <link name="right_arm_right_fingertip">
    <inertial>
      <origin xyz="0. 0. 0." rpy="0. 0. 0."/>
      <mass value="0.01"/>
      <inertia ixx="0." ixy="0." ixz="0." iyy="0." iyz="0." izz="0."/>
    </inertial>
    <visual>
      <origin xyz="-0.0016779 -1.3538252 1.0677084" rpy="1.570336 0.0008613 3.1415923"/>
      <geometry>
        <mesh filename="meshes/right_arm_right_fingertip_collisions.obj" scale="1. 1. 1."/>
      </geometry>
    </visual>
    <visual>
      <origin xyz="-0.0016779 -1.3538252 1.0677084" rpy="1.570336 0.0008613 3.1415923"/>
      <geometry>
        <mesh filename="meshes/right_arm_right_fingertip_visuals_mesh_0.obj" scale="1. 1. 1."/>
      </geometry>
    </visual>
    <visual>
      <origin xyz="-0.0016779 -1.3538252 1.0677084" rpy="1.570336 0.0008613 3.1415923"/>
      <geometry>
        <mesh filename="meshes/right_arm_right_fingertip_visuals_mesh_1.obj" scale="1. 1. 1."/>
      </geometry>
    </visual>
    <visual>
      <origin xyz="-0.0016779 -1.3538252 1.0677084" rpy="1.570336 0.0008613 3.1415923"/>
      <geometry>
        <mesh filename="meshes/right_arm_right_fingertip_visuals_mesh_2.obj" scale="1. 1. 1."/>
      </geometry>
    </visual>
    <collision>
      <origin xyz="-0.0016779 -1.3538252 1.0677084" rpy="1.570336 0.0008613 3.1415923"/>
      <geometry>
        <mesh filename="meshes/right_arm_right_fingertip_collisions.obj" scale="1. 1. 1."/>
      </geometry>
    </collision>
  </link>
  <link name="right_arm_right_inner_finger">
    <inertial>
      <origin xyz="0. 0. 0." rpy="0. 0. 0."/>
      <mass value="0.000001"/>
      <inertia ixx="0." ixy="0." ixz="0." iyy="0." iyz="0." izz="0."/>
    </inertial>
    <visual>
      <origin xyz="-0.0433971 -1.2310503 1.0665416" rpy="0.0000007 -0.0000603 3.132593 "/>
      <geometry>
        <mesh filename="meshes/right_arm_right_inner_finger_visuals.obj" scale="1. 1. 1."/>
      </geometry>
    </visual>
  </link>
  <link name="right_arm_right_inner_knuckle">
    <inertial>
      <origin xyz="0. 0. 0." rpy="0. 0. 0."/>
      <mass value="0.000001"/>
      <inertia ixx="0." ixy="0." ixz="0." iyy="0." iyz="0." izz="0."/>
    </inertial>
    <visual>
      <origin xyz="0.0499387 -0.0107622 -0.000032 " rpy="0.000984 -0.0000793 2.3017263"/>
      <geometry>
        <mesh filename="meshes/right_arm_right_inner_knuckle_visuals.obj" scale="1. 1. 1."/>
      </geometry>
    </visual>
  </link>
  <link name="right_arm_right_outer_finger">
    <inertial>
      <origin xyz="0. 0. 0." rpy="0. 0. 0."/>
      <mass value="0.000001"/>
      <inertia ixx="0." ixy="0." ixz="0." iyy="0." iyz="0." izz="0."/>
    </inertial>
    <visual>
      <origin xyz="0.0506371 -1.2126998 1.0665375" rpy="0.0000384 -0.0000451 2.3059108"/>
      <geometry>
        <mesh filename="meshes/right_arm_right_outer_finger_visuals.obj" scale="1. 1. 1."/>
      </geometry>
    </visual>
  </link>
  <link name="right_arm_right_outer_knuckle">
    <inertial>
      <origin xyz="0. 0. 0." rpy="0. 0. 0."/>
      <mass value="0.000001"/>
      <inertia ixx="0." ixy="0." ixz="0." iyy="0." iyz="0." izz="0."/>
    </inertial>
    <visual>
      <origin xyz="0.0508977 0.0048152 -0.0000422" rpy="0.0009838 -0.0000816 2.3041008"/>
      <geometry>
        <mesh filename="meshes/right_arm_right_outer_knuckle_visuals.obj" scale="1. 1. 1."/>
      </geometry>
    </visual>
  </link>
  <link name="right_arm_robotiq_arg2f_base_link">
    <inertial>
      <origin xyz="0. 0. 0." rpy="0. 0. 0."/>
      <mass value="0.000001"/>
      <inertia ixx="0." ixy="0." ixz="0." iyy="0." iyz="0." izz="0."/>
    </inertial>
    <visual>
      <origin xyz="-0.0000002 0.000242 -0.0000001" rpy="-0.0006052 0.0006863 -3.1413505"/>
      <geometry>
        <mesh filename="meshes/right_arm_robotiq_arg2f_base_link_visuals.obj" scale="1. 1. 1."/>
      </geometry>
    </visual>
  </link>
  <link name="right_base_link">
    <inertial>
      <origin xyz="0. 0. 0." rpy="0. 0. 0."/>
      <mass value="1.697"/>
      <inertia ixx="0." ixy="0." ixz="0." iyy="0." iyz="0." izz="0."/>
    </inertial>
    <visual>
      <origin xyz="0. -0.03 0.17446" rpy="1.5707963 0. 0. "/>
      <geometry>
        <mesh filename="meshes/right_base_link_collisions.obj" scale="1. 1. 1."/>
      </geometry>
    </visual>
    <visual>
      <origin xyz="0. -0.03 0.17446" rpy="1.5707963 0. 0. "/>
      <geometry>
        <mesh filename="meshes/right_base_link_visuals_mesh_0.obj" scale="1. 1. 1."/>
      </geometry>
    </visual>
    <visual>
      <origin xyz="0. -0.03 0.17446" rpy="1.5707963 0. 0. "/>
      <geometry>
        <mesh filename="meshes/right_base_link_visuals_mesh_1.obj" scale="1. 1. 1."/>
      </geometry>
    </visual>
    <collision>
      <origin xyz="0. -0.03 0.17446" rpy="1.5707963 0. 0. "/>
      <geometry>
        <mesh filename="meshes/right_base_link_collisions.obj" scale="1. 1. 1."/>
      </geometry>
    </collision>
  </link>
  <link name="right_bracelet_link">
    <inertial>
      <origin xyz="0. 0. 0." rpy="0. 0. 0."/>
      <mass value="0.5"/>
      <inertia ixx="0." ixy="0." ixz="0." iyy="0." iyz="0." izz="0."/>
    </inertial>
    <visual>
      <origin xyz="-0.0000001 0.0000049 0. " rpy="0.0000036 1.5707963 0. "/>
      <geometry>
        <mesh filename="meshes/right_bracelet_link_collisions.obj" scale="1. 1. 1."/>
      </geometry>
    </visual>
    <visual>
      <origin xyz="-0.0000001 0.0000049 0. " rpy="0.0000036 1.5707963 0. "/>
      <geometry>
        <mesh filename="meshes/right_bracelet_link_visuals_mesh_0.obj" scale="1. 1. 1."/>
      </geometry>
    </visual>
    <visual>
      <origin xyz="-0.0000001 0.0000049 0. " rpy="0.0000036 1.5707963 0. "/>
      <geometry>
        <mesh filename="meshes/right_bracelet_link_visuals_mesh_1.obj" scale="1. 1. 1."/>
      </geometry>
    </visual>
    <collision>
      <origin xyz="-0.0000001 0.0000049 0. " rpy="0.0000036 1.5707963 0. "/>
      <geometry>
        <mesh filename="meshes/right_bracelet_link_collisions.obj" scale="1. 1. 1."/>
      </geometry>
    </collision>
  </link>
  <link name="right_end_effector_link">
    <inertial>
      <origin xyz="0. 0. 0." rpy="0. 0. 0."/>
      <mass value="0.000001"/>
      <inertia ixx="0." ixy="0." ixz="0." iyy="0." iyz="0." izz="0."/>
    </inertial>
  </link>
  <link name="right_forearm_link">
    <inertial>
      <origin xyz="0. 0. 0." rpy="0. 0. 0."/>
      <mass value="0.9302"/>
      <inertia ixx="0." ixy="0." ixz="0." iyy="0." iyz="0." izz="0."/>
    </inertial>
    <visual>
      <origin xyz="-0.000005 0. 0. " rpy="-0.0000036 1.5707963 0. "/>
      <geometry>
        <mesh filename="meshes/right_forearm_link_collisions.obj" scale="1. 1. 1."/>
      </geometry>
    </visual>
    <visual>
      <origin xyz="-0.000005 0. 0. " rpy="-0.0000036 1.5707963 0. "/>
      <geometry>
        <mesh filename="meshes/right_forearm_link_visuals_mesh_0.obj" scale="1. 1. 1."/>
      </geometry>
    </visual>
    <visual>
      <origin xyz="-0.000005 0. 0. " rpy="-0.0000036 1.5707963 0. "/>
      <geometry>
        <mesh filename="meshes/right_forearm_link_visuals_mesh_1.obj" scale="1. 1. 1."/>
      </geometry>
    </visual>
    <collision>
      <origin xyz="-0.000005 0. 0. " rpy="-0.0000036 1.5707963 0. "/>
      <geometry>
        <mesh filename="meshes/right_forearm_link_collisions.obj" scale="1. 1. 1."/>
      </geometry>
    </collision>
  </link>
  <link name="right_half_arm_1_link">
    <inertial>
      <origin xyz="0. 0. 0." rpy="0. 0. 0."/>
      <mass value="1.1636"/>
      <inertia ixx="0." ixy="0." ixz="0." iyy="0." iyz="0." izz="0."/>
    </inertial>
    <visual>
      <origin xyz="-0.000005 0. 0. " rpy="-0.0000036 1.5707963 0. "/>
      <geometry>
        <mesh filename="meshes/right_half_arm_1_link_collisions.obj" scale="1. 1. 1."/>
      </geometry>
    </visual>
    <visual>
      <origin xyz="-0.000005 0. 0. " rpy="-0.0000036 1.5707963 0. "/>
      <geometry>
        <mesh filename="meshes/right_half_arm_1_link_visuals_mesh_0.obj" scale="1. 1. 1."/>
      </geometry>
    </visual>
    <visual>
      <origin xyz="-0.000005 0. 0. " rpy="-0.0000036 1.5707963 0. "/>
      <geometry>
        <mesh filename="meshes/right_half_arm_1_link_visuals_mesh_1.obj" scale="1. 1. 1."/>
      </geometry>
    </visual>
    <collision>
      <origin xyz="-0.000005 0. 0. " rpy="-0.0000036 1.5707963 0. "/>
      <geometry>
        <mesh filename="meshes/right_half_arm_1_link_collisions.obj" scale="1. 1. 1."/>
      </geometry>
    </collision>
  </link>
  <link name="right_half_arm_2_link">
    <inertial>
      <origin xyz="0. 0. 0." rpy="0. 0. 0."/>
      <mass value="1.1636"/>
      <inertia ixx="0." ixy="0." ixz="0." iyy="0." iyz="0." izz="0."/>
    </inertial>
    <visual>
      <origin xyz="0. -0.000005 0. " rpy="0.0000036 1.5707963 0. "/>
      <geometry>
        <mesh filename="meshes/right_half_arm_2_link_collisions.obj" scale="1. 1. 1."/>
      </geometry>
    </visual>
    <visual>
      <origin xyz="0. -0.000005 0. " rpy="0.0000036 1.5707963 0. "/>
      <geometry>
        <mesh filename="meshes/right_half_arm_2_link_visuals_mesh_0.obj" scale="1. 1. 1."/>
      </geometry>
    </visual>
    <visual>
      <origin xyz="0. -0.000005 0. " rpy="0.0000036 1.5707963 0. "/>
      <geometry>
        <mesh filename="meshes/right_half_arm_2_link_visuals_mesh_1.obj" scale="1. 1. 1."/>
      </geometry>
    </visual>
    <collision>
      <origin xyz="0. -0.000005 0. " rpy="0.0000036 1.5707963 0. "/>
      <geometry>
        <mesh filename="meshes/right_half_arm_2_link_collisions.obj" scale="1. 1. 1."/>
      </geometry>
    </collision>
  </link>
  <link name="right_shoulder_link">
    <inertial>
      <origin xyz="0. 0. 0." rpy="0. 0. 0."/>
      <mass value="1.3773"/>
      <inertia ixx="0." ixy="0." ixz="0." iyy="0." iyz="0." izz="0."/>
    </inertial>
    <visual>
      <origin xyz="0. 0. 0." rpy="-0.000006 1.5707963 0.0000012"/>
      <geometry>
        <mesh filename="meshes/right_shoulder_link_collisions.obj" scale="1. 1. 1."/>
      </geometry>
    </visual>
    <visual>
      <origin xyz="0. 0. 0." rpy="-0.000006 1.5707963 0.0000012"/>
      <geometry>
        <mesh filename="meshes/right_shoulder_link_visuals_mesh_0.obj" scale="1. 1. 1."/>
      </geometry>
    </visual>
    <visual>
      <origin xyz="0. 0. 0." rpy="-0.000006 1.5707963 0.0000012"/>
      <geometry>
        <mesh filename="meshes/right_shoulder_link_visuals_mesh_1.obj" scale="1. 1. 1."/>
      </geometry>
    </visual>
    <collision>
      <origin xyz="0. 0. 0." rpy="-0.000006 1.5707963 0.0000012"/>
      <geometry>
        <mesh filename="meshes/right_shoulder_link_collisions.obj" scale="1. 1. 1."/>
      </geometry>
    </collision>
  </link>
  <link name="right_spherical_wrist_1_link">
    <inertial>
      <origin xyz="0. 0. 0." rpy="0. 0. 0."/>
      <mass value="0.6781"/>
      <inertia ixx="0." ixy="0." ixz="0." iyy="0." iyz="0." izz="0."/>
    </inertial>
    <visual>
      <origin xyz="0. 0.000005 0. " rpy="0.0000036 1.5707963 0. "/>
      <geometry>
        <mesh filename="meshes/right_spherical_wrist_1_link_collisions.obj" scale="1. 1. 1."/>
      </geometry>
    </visual>
    <visual>
      <origin xyz="0. 0.000005 0. " rpy="0.0000036 1.5707963 0. "/>
      <geometry>
        <mesh filename="meshes/right_spherical_wrist_1_link_visuals_mesh_0.obj" scale="1. 1. 1."/>
      </geometry>
    </visual>
    <visual>
      <origin xyz="0. 0.000005 0. " rpy="0.0000036 1.5707963 0. "/>
      <geometry>
        <mesh filename="meshes/right_spherical_wrist_1_link_visuals_mesh_1.obj" scale="1. 1. 1."/>
      </geometry>
    </visual>
    <collision>
      <origin xyz="0. 0.000005 0. " rpy="0.0000036 1.5707963 0. "/>
      <geometry>
        <mesh filename="meshes/right_spherical_wrist_1_link_collisions.obj" scale="1. 1. 1."/>
      </geometry>
    </collision>
  </link>
  <link name="right_spherical_wrist_2_link">
    <inertial>
      <origin xyz="0. 0. 0." rpy="0. 0. 0."/>
      <mass value="0.6781"/>
      <inertia ixx="0." ixy="0." ixz="0." iyy="0." iyz="0." izz="0."/>
    </inertial>
    <visual>
      <origin xyz="0.000005 0. 0. " rpy="-0.0000036 1.5707963 0. "/>
      <geometry>
        <mesh filename="meshes/right_spherical_wrist_2_link_collisions.obj" scale="1. 1. 1."/>
      </geometry>
    </visual>
    <visual>
      <origin xyz="0.000005 0. 0. " rpy="-0.0000036 1.5707963 0. "/>
      <geometry>
        <mesh filename="meshes/right_spherical_wrist_2_link_visuals_mesh_0.obj" scale="1. 1. 1."/>
      </geometry>
    </visual>
    <visual>
      <origin xyz="0.000005 0. 0. " rpy="-0.0000036 1.5707963 0. "/>
      <geometry>
        <mesh filename="meshes/right_spherical_wrist_2_link_visuals_mesh_1.obj" scale="1. 1. 1."/>
      </geometry>
    </visual>
    <collision>
      <origin xyz="0.000005 0. 0. " rpy="-0.0000036 1.5707963 0. "/>
      <geometry>
        <mesh filename="meshes/right_spherical_wrist_2_link_collisions.obj" scale="1. 1. 1."/>
      </geometry>
    </collision>
  </link>
  <link name="right_tool_frame">
    <inertial>
      <origin xyz="0. 0. 0." rpy="0. 0. 0."/>
      <mass value="0.000001"/>
      <inertia ixx="0." ixy="0." ixz="0." iyy="0." iyz="0." izz="0."/>
    </inertial>
  </link>
</robot>
