<?xml version="1.0" ?>
<!-- =================================================================================== -->
<!-- |    This document was autogenerated by xacro from ridgeback.urdf.xacro           | -->
<!-- |    EDITING THIS FILE BY HAND IS NOT RECOMMENDED                                 | -->
<!-- =================================================================================== -->
<robot name="ridgeback">
  <material name="dark_grey">
    <color rgba="0.2 0.2 0.2 1.0"/>
  </material>
  <material name="light_grey">
    <color rgba="0.4 0.4 0.4 1.0"/>
  </material>
  <material name="red">
    <color rgba="0.8 0.0 0.0 1.0"/>
  </material>
  <material name="white">
    <color rgba="0.9 0.9 0.9 1.0"/>
  </material>
  <material name="yellow">
    <color rgba="0.8 0.8 0.0 1.0"/>
  </material>
  <material name="black">
    <color rgba="0.15 0.15 0.15 1.0"/>
  </material>
  <!-- <link name="front_rocker_link">
    <visual>
      <origin rpy="1.5707963267948966 0 1.5707963267948966" xyz="0 0 0"/>
      <geometry>
        <mesh filename="./meshes/rocker.stl"/>
      </geometry>
      <material name="black"/>
    </visual>
    <inertial>
      <origin rpy="1.5707963267948966 0 1.5707963267948966" xyz="0 0 0"/>
      <mass value="10.267"/>
      <inertia ixx="0.0288" ixy="2.20484e-6" ixz="-1.3145e-5" iyy="0.4324" iyz="1.8944e-3" izz="0.4130"/>
    </inertial>
  </link>
  <joint name="front_rocker" type="revolute">
    <parent link="axle_link"/>
    <child link="front_rocker_link"/>
    <origin rpy="0 0 0" xyz="0.319 0 0"/>
    <axis xyz="1 0 0"/>
    <limit effort="0" lower="-0.08726" upper="0.08726" velocity="0"/>
  </joint> -->
  <!-- <link name="front_left_wheel_link">
    <visual>
      <origin rpy="1.5707963267948966 0 0" xyz="0 0 0"/>
      <geometry>
        <mesh filename="./meshes/wheel.stl"/>
      </geometry>
      <material name="black"/>
    </visual>
    <collision>
      <origin rpy="1.5707963267948966 0 0" xyz="0 0 0"/>
      <geometry>
        <cylinder length="0.079" radius="0.0759"/>
      </geometry>
    </collision>
    <inertial>
      <origin rpy="0 0 0" xyz="0 0 0"/>
      <mass value="2.3"/>
      <inertia ixx="3.3212e-3" ixy="0" ixz="0" iyy="6.6424e-3" iyz="0" izz="3.3212e-3"/>
    </inertial>
  </link>
  <joint name="front_left_wheel" type="continuous">
    <parent link="front_rocker_link"/>
    <child link="front_left_wheel_link"/>
    <origin rpy="0 0 0" xyz="0 0.27549999999999997 0"/>
    <axis xyz="0 1 0"/>
  </joint> -->
  <!-- <link name="front_right_wheel_link">
    <visual>
      <origin rpy="1.5707963267948966 0 0" xyz="0 0 0"/>
      <geometry>
        <mesh filename="./meshes/wheel.stl"/>
      </geometry>
      <material name="black"/>
    </visual>
    <collision>
      <origin rpy="1.5707963267948966 0 0" xyz="0 0 0"/>
      <geometry>
        <cylinder length="0.079" radius="0.0759"/>
      </geometry>
    </collision>
    <inertial>
      <origin rpy="0 0 0" xyz="0 0 0"/>
      <mass value="2.3"/>
      <inertia ixx="3.3212e-3" ixy="0" ixz="0" iyy="6.6424e-3" iyz="0" izz="3.3212e-3"/>
    </inertial>
  </link>
  <joint name="front_right_wheel" type="continuous">
    <parent link="front_rocker_link"/>
    <child link="front_right_wheel_link"/>
    <origin rpy="0 0 0" xyz="0 -0.27549999999999997 0"/>
    <axis xyz="0 1 0"/>
  </joint> -->

  <link name="rear_rocker_link">
    <visual>
      <origin rpy="1.5707963267948966 0 1.5707963267948966" xyz="0 0 0"/>
      <geometry>
        <mesh filename="./meshes/rocker.stl"/>
      </geometry>
      <material name="black"/>
    </visual>
    <inertial>
      <origin rpy="1.5707963267948966 0 1.5707963267948966" xyz="0 0 0"/>
      <mass value="10.267"/>
      <inertia ixx="0.0288" ixy="2.20484e-6" ixz="-1.3145e-5" iyy="0.4324" iyz="1.8944e-3" izz="0.4130"/>
    </inertial>
  </link>
  <joint name="rear_rocker" type="fixed">
    <parent link="axle_link"/>
    <child link="rear_rocker_link"/>
    <origin rpy="0 0 0" xyz="-0.319 0 0"/>
    <axis xyz="1 0 0"/>
    <limit effort="0" velocity="0"/>
  </joint>
  <!-- <link name="rear_left_wheel_link">
    <visual>
      <origin rpy="1.5707963267948966 0 0" xyz="0 0 0"/>
      <geometry>
        <mesh filename="./meshes/wheel.stl"/>
      </geometry>
      <material name="black"/>
    </visual>
    <collision>
      <origin rpy="1.5707963267948966 0 0" xyz="0 0 0"/>
      <geometry>
        <cylinder length="0.079" radius="0.0759"/>
      </geometry>
    </collision>
    <inertial>
      <origin rpy="0 0 0" xyz="0 0 0"/>
      <mass value="2.3"/>
      <inertia ixx="3.3212e-3" ixy="0" ixz="0" iyy="6.6424e-3" iyz="0" izz="3.3212e-3"/>
    </inertial>
  </link>
  <joint name="rear_left_wheel" type="continuous">
    <parent link="rear_rocker_link"/>
    <child link="rear_left_wheel_link"/>
    <origin rpy="0 0 0" xyz="0 0.27549999999999997 0"/>
    <axis xyz="0 1 0"/>
  </joint> -->

  <!-- <link name="rear_right_wheel_link">
    <visual>
      <origin rpy="1.5707963267948966 0 0" xyz="0 0 0"/>
      <geometry>
        <mesh filename="./meshes/wheel.stl"/>
      </geometry>
      <material name="black"/>
    </visual>
    <collision>
      <origin rpy="1.5707963267948966 0 0" xyz="0 0 0"/>
      <geometry>
        <cylinder length="0.079" radius="0.0759"/>
      </geometry>
    </collision>
    <inertial>
      <origin rpy="0 0 0" xyz="0 0 0"/>
      <mass value="2.3"/>
      <inertia ixx="3.3212e-3" ixy="0" ixz="0" iyy="6.6424e-3" iyz="0" izz="3.3212e-3"/>
    </inertial>
  </link>
  <joint name="rear_right_wheel" type="continuous">
    <parent link="rear_rocker_link"/>
    <child link="rear_right_wheel_link"/>
    <origin rpy="0 0 0" xyz="0 -0.27549999999999997 0"/>
    <axis xyz="0 1 0"/>
  </joint> -->

  <link name="base_link"/>
  <joint name="base_link_joint" type="fixed">
    <origin rpy="0 0 0" xyz="0 0 0"/>
    <parent link="base_link"/>
    <child link="chassis_link"/>
  </joint>
  <link name="chassis_link">
    <visual>
      <origin rpy="0 0 0" xyz="0 0 0"/>
      <geometry>
        <mesh filename="./meshes/body.stl"/>
      </geometry>
      <material name="black"/>
    </visual>
    <collision>
      <origin xyz="0 0 0"/>
      <geometry>
        <mesh filename="./meshes/body-collision.stl"/>
      </geometry>
    </collision>
    <inertial>
      <origin rpy="1.5707963267948966 0 1.5707963267948966" xyz="0.012 0.002 0.067"/>
      <mass value="165.304"/>
      <inertia ixx="4.4744" ixy="0.03098" ixz="0.003647" iyy="7.1624" iyz="0.1228" izz="4.6155"/>
    </inertial>
  </link>
  <joint name="right_side_cover_link_joint" type="fixed">
    <origin rpy="0 0 0" xyz="0 0 0"/>
    <parent link="chassis_link"/>
    <child link="right_side_cover_link"/>
  </joint>
  <joint name="left_side_cover_link_joint" type="fixed">
    <origin rpy="0 0 0" xyz="0 0 0"/>
    <parent link="chassis_link"/>
    <child link="left_side_cover_link"/>
  </joint>
  <link name="left_side_cover_link">
    <visual>
      <origin rpy="0 0 3.141592653589793" xyz="0 0 0"/>
      <geometry>
        <mesh filename="./meshes/side-cover.stl"/>
      </geometry>
      <material name="yellow"/>
    </visual>
  </link>
  <link name="right_side_cover_link">
    <visual>
      <origin rpy="0 0 0" xyz="0 0 0"/>
      <geometry>
        <mesh filename="./meshes/side-cover.stl"/>
      </geometry>
      <material name="yellow"/>
    </visual>
  </link>
  <joint name="front_cover_link_joint" type="fixed">
    <origin rpy="0 0 0" xyz="0 0 0"/>
    <parent link="chassis_link"/>
    <child link="front_cover_link"/>
  </joint>
  <link name="front_cover_link">
    <visual>
      <origin rpy="0 0 0" xyz="0 0 0"/>
      <geometry>
        <mesh filename="./meshes/end-cover.stl"/>
      </geometry>
      <material name="black"/>
    </visual>
  </link>
  <joint name="rear_cover_link_joint" type="fixed">
    <origin rpy="0 0 0" xyz="0 0 0"/>
    <parent link="chassis_link"/>
    <child link="rear_cover_link"/>
  </joint>
  <link name="rear_cover_link">
    <visual>
      <origin rpy="0 0 3.141592653589793" xyz="0 0 0"/>
      <geometry>
        <mesh filename="./meshes/end-cover.stl"/>
      </geometry>
      <material name="black"/>
    </visual>
  </link>
  <joint name="front_lights_link_joint" type="fixed">
    <origin rpy="0 0 0" xyz="0 0 0"/>
    <parent link="chassis_link"/>
    <child link="front_lights_link"/>
  </joint>
  <joint name="rear_lights_link_joint" type="fixed">
    <origin rpy="0 0 0" xyz="0 0 0"/>
    <parent link="chassis_link"/>
    <child link="rear_lights_link"/>
  </joint>
  <link name="front_lights_link">
    <visual>
      <origin rpy="0 0 0" xyz="0 0 0"/>
      <geometry>
        <mesh filename="./meshes/lights.stl"/>
      </geometry>
      <material name="white"/>
    </visual>
  </link>
  <link name="rear_lights_link">
    <visual>
      <origin rpy="0 0 3.141592653589793" xyz="0 0 0"/>
      <geometry>
        <mesh filename="./meshes/lights.stl"/>
      </geometry>
      <material name="red"/>
    </visual>
  </link>
  <joint name="top_link_joint" type="fixed">
    <origin rpy="0 0 0" xyz="0 0 0"/>
    <parent link="chassis_link"/>
    <child link="top_link"/>
  </joint>
  <link name="top_link">
    <visual>
      <origin rpy="0 0 0" xyz="0 0 0"/>
      <geometry>
        <mesh filename="./meshes/top.stl"/>
      </geometry>
      <material name="black"/>
    </visual>
    <collision>
      <origin rpy="0 0 0" xyz="0 0 0"/>
      <geometry>
        <mesh filename="./meshes/top.stl"/>
      </geometry>
    </collision>
  </link>
  <joint name="axle_joint" type="fixed">
    <origin rpy="0 0 0" xyz="0 0 0.05"/>
    <parent link="chassis_link"/>
    <child link="axle_link"/>
  </joint>
  <link name="axle_link">
    <visual>
      <origin rpy="0 1.5707963267948966 0" xyz="0 0 0"/>
      <geometry>
        <mesh filename="./meshes/axle.stl"/>
      </geometry>
      <material name="black"/>
    </visual>
  </link>
  <link name="imu_link">
    <inertial>
      <mass value="0.001"/>
      <origin rpy="0 0 0" xyz="0 0 0"/>
      <inertia ixx="1e-09" ixy="0.0" ixz="0.0" iyy="1e-09" iyz="0.0" izz="1e-09"/>
    </inertial>
  </link>
  <joint name="imu_joint" type="fixed">
    <parent link="chassis_link"/>
    <child link="imu_link"/>
    <origin rpy="0 0 0" xyz="0.2085 -0.2902 0.1681"/>
  </joint>
  <link name="mid_mount"/>
  <joint name="mid_mount_joint" type="fixed">
    <parent link="base_link"/>
    <child link="mid_mount"/>
    <origin rpy="0 0 0" xyz="0 0 0.28"/>
  </joint>

  <!-- All static links get collapsed down to base_link in Gazebo, so that's
       the one to apply the colour to (in Gazebo 5+). -->
  <gazebo reference="base_link">
    <material>Gazebo/DarkGrey</material>
    <gravity>true</gravity>
  </gazebo>
  <!-- Individual link colouring still needed in Gazebo 2.x -->
  <gazebo reference="chassis_link">
    <material>Gazebo/DarkGrey</material>
  </gazebo>
  <gazebo reference="top_link">
    <material>Gazebo/DarkGrey</material>
  </gazebo>
  <gazebo reference="left_side_cover_link">
    <material>Gazebo/Yellow</material>
  </gazebo>
  <gazebo reference="right_side_cover_link">
    <material>Gazebo/Yellow</material>
  </gazebo>
  <gazebo reference="front_cover_link">
    <material>Gazebo/DarkGrey</material>
  </gazebo>
  <gazebo reference="rear_cover_link">
    <material>Gazebo/DarkGrey</material>
  </gazebo>
  <gazebo reference="front_lights_link">
    <material>Gazebo/White</material>
  </gazebo>
  <gazebo reference="rear_lights_link">
    <material>Gazebo/Red</material>
  </gazebo>
  <gazebo reference="front_rocker_link">
    <material>Gazebo/DarkGrey</material>
  </gazebo>
  <gazebo reference="rear_rocker_link">
    <material>Gazebo/DarkGrey</material>
  </gazebo>
  <gazebo reference="axle_link">
    <material>Gazebo/DarkGrey</material>
  </gazebo>
  <!-- Wheel friction to zero, as movement is handled by applying forces at
       the body level. -->
  <gazebo reference="front_left_wheel_link">
    <material>Gazebo/DarkGrey</material>
    <mu1>0.0</mu1>
    <mu2>0.0</mu2>
  </gazebo>
  <gazebo reference="front_right_wheel_link">
    <material>Gazebo/DarkGrey</material>
    <mu1>0.0</mu1>
    <mu2>0.0</mu2>
  </gazebo>
  <gazebo reference="rear_left_wheel_link">
    <material>Gazebo/DarkGrey</material>
    <mu1>0.0</mu1>
    <mu2>0.0</mu2>
  </gazebo>
  <gazebo reference="rear_right_wheel_link">
    <material>Gazebo/DarkGrey</material>
    <mu1>0.0</mu1>
    <mu2>0.0</mu2>
  </gazebo>
  <!-- This is an wheel-level solution to possibly revisit at a future date. -->
  <!--<gazebo>
    <plugin name="mecanum_gazebo" filename="libmecanum_force_plugin.so">
      <wheelJointName>front_left_wheel</wheelJointName>
      <forceScaleFactor>1</forceScaleFactor>
    </plugin>
    <plugin name="mecanum_gazebo" filename="libmecanum_force_plugin.so">
      <wheelJointName>front_right_wheel</wheelJointName>
      <forceScaleFactor>-1</forceScaleFactor>
    </plugin>
    <plugin name="mecanum_gazebo" filename="libmecanum_force_plugin.so">
      <wheelJointName>rear_left_wheel</wheelJointName>
      <forceScaleFactor>-1</forceScaleFactor>
    </plugin>
    <plugin name="mecanum_gazebo" filename="libmecanum_force_plugin.so">
      <wheelJointName>rear_right_wheel</wheelJointName>
      <forceScaleFactor>1</forceScaleFactor>
    </plugin>
  </gazebo> -->
  <!--
    As you add to this URDF, please be aware that both the robot and
    simulation include it. You must retain compatibility with all of
    the following launch files:

    ridgeback_viz/launch/view_model.launch
    ridgeback_gazebo/launch/ridgeback_world.launch
    ridgeback_base/launch/base.launch
  -->
  <!-- Link for the rear auxiliary plate mesh -->
  <link name="rear_plate_base_link">
    <visual>
      <geometry>
        <mesh filename="./meshes/aux_plate_200.stl"/>
      </geometry>
    </visual>
    <collision>
      <geometry>
        <box size="0.38 0.79 0.206"/>
      </geometry>
      <origin rpy="0 0 0" xyz="0.19 0 0.103"/>
    </collision>
  </link>
  <joint name="rear_plate_base_joint" type="fixed">
    <parent link="mid_mount"/>
    <child link="rear_plate_base_link"/>
    <origin rpy="0 0 3.14159" xyz="-0.09 0.0 0.0"/>
  </joint>
  <!-- Add a link to the aux plate for additional payloads -->
  <link name="rear_plate_link"/>
  <joint name="rear_plate_joint" type="fixed">
    <parent link="rear_plate_base_link"/>
    <child link="rear_plate_link"/>
    <origin rpy="0 0 3.14159" xyz="-0.140 0.0 0.2063"/>
  </joint>
  <!-- - - - - - - - - - - - - - EWELLIX LIFT - - - - - - - - - - - - - -->
  <!-- Lift base link -->
  <link name="ewellix_lift_base_link">
    <visual>
      <origin rpy="0 0 1.5707963267948966" xyz="0 0 0"/>
      <geometry>
        <mesh filename="./meshes/ewellix_lift_base_500mm.stl" scale="0.001 0.001 0.001"/>
      </geometry>
      <material name="grey">
        <color rgba="0.7 0.7 0.7 1"/>
      </material>
    </visual>
    <collision>
      <origin rpy="0 0 1.5707963267948966" xyz="0.0 0 0.0"/>
      <geometry>
        <mesh filename="./meshes/ewellix_lift_base_500mm.stl" scale="0.001 0.001 0.001"/>
      </geometry>
    </collision>
    <inertial>
      <mass value="20"/>
      <origin rpy="0 0 0" xyz="0 0 0"/>
      <inertia ixx="1e-1" ixy="0" ixz="0" iyy="1e-1" iyz="0" izz="1e-1"/>
    </inertial>
  </link>
  <!-- Lift base link joint -->
  <joint name="ewellix_lift_base_joint" type="fixed">
    <origin rpy="0 0 0" xyz="0.0 0.0 0.0"/>
    <parent link="mid_mount"/>
    <child link="ewellix_lift_base_link"/>
  </joint>
  <!-- Lift top link -->
  <link name="ewellix_lift_top_link">
    <visual>
      <origin rpy="0 0 -1.5707963267948966" xyz="0 0 0"/>
      <geometry>
        <mesh filename="./meshes/ewellix_lift_top_500mm.stl" scale="0.001 0.001 0.001"/>
      </geometry>
      <material name="grey">
        <color rgba="0.7 0.7 0.7 1"/>
      </material>
    </visual>
    <collision>
      <origin rpy="0 0 -1.5707963267948966" xyz="0.0 0 0.0"/>
      <geometry>
        <mesh filename="./meshes/ewellix_lift_top_500mm.stl" scale="0.001 0.001 0.001"/>
      </geometry>
    </collision>
    <inertial>
      <mass value="2"/>
      <origin rpy="0 0 0" xyz="0 0 0"/>
      <inertia ixx="0.2e-1" ixy="0" ixz="0" iyy="0.2e-1" iyz="0" izz="0.2e-1"/>
    </inertial>
  </link>
  <!-- Lift top link joint -->
  <joint name="ewellix_lift_top_joint" type="prismatic">
    <parent link="ewellix_lift_base_link"/>
    <child link="ewellix_lift_top_link"/>
    <origin rpy="0 0 0" xyz="0 0 0.52"/>
    <limit effort="100000" lower="0.0" upper="0.5" velocity="0.088"/>
    <axis xyz="0 0 1"/>
  </joint>
  <!--
        PositionJointInterface
        VelocityJointInterface
        EffortJointInterface
    -->

  <!-- Link for the dual Gen3 Manipulator Mount -->
  <link name="dual_gen3_base_link">
    <visual>
      <geometry>
        <mesh filename="./meshes/dual_gen3_mount.stl"/>
      </geometry>
    </visual>
    <collision>
      <geometry>
        <box size="0.14 0.14 0.256"/>
      </geometry>
      <origin rpy="0 0 0" xyz="0 0 0.128"/>
    </collision>
  </link>
  <joint name="dual_gen3_base_joint" type="fixed">
    <parent link="ewellix_lift_top_link"/>
    <child link="dual_gen3_base_link"/>
    <origin rpy="0 0 0" xyz="0.0 0.0 0.0"/>
  </joint>
  <!-- Add a link to the top of the dual gen3 mount for additional payloads -->
  <link name="gen3_plate_link"/>
  <joint name="gen3_plate_joint" type="fixed">
    <parent link="dual_gen3_base_link"/>
    <child link="gen3_plate_link"/>
    <origin rpy="0 0 0" xyz="0.0 0.0 0.256"/>
  </joint>
  <!-- Add the Gen3 Manipulators. Their position may be defined by environment variables -->
  <!-- Run the macros -->
  <link name="left_kinova_arm_base_link">
    <inertial>
      <origin rpy="0 0 0" xyz="-0.000648 -0.000166 0.084487"/>
      <mass value="1.697"/>
      <inertia ixx="0.004622" ixy="9E-06" ixz="6E-05" iyy="0.004495" iyz="9E-06" izz="0.002079"/>
    </inertial>
    <visual>
      <origin rpy="0 0 0" xyz="0 0 0"/>
      <geometry>
        <mesh filename="./meshes/kortex_description/arms/gen3/7dof/meshes/base_link.STL"/>
      </geometry>
      <material name="">
        <color rgba="0.75294 0.75294 0.75294 1"/>
      </material>
    </visual>
    <collision>
      <origin rpy="0 0 0" xyz="0 0 0"/>
      <geometry>
        <mesh filename="./meshes/kortex_description/arms/gen3/7dof/meshes/base_link.STL"/>
      </geometry>
    </collision>
  </link>
  <link name="left_kinova_arm_shoulder_link">
    <inertial>
      <origin rpy="0 0 0" xyz="-2.3E-05 -0.010364 -0.07336"/>
      <mass value="1.3773"/>
      <inertia ixx="0.00457" ixy="1E-06" ixz="2E-06" iyy="0.004831" iyz="0.000448" izz="0.001409"/>
    </inertial>
    <visual>
      <origin rpy="0 0 0" xyz="0 0 0"/>
      <geometry>
        <mesh filename="./meshes/kortex_description/arms/gen3/7dof/meshes/shoulder_link.STL"/>
      </geometry>
      <material name="">
        <color rgba="0.75294 0.75294 0.75294 1"/>
      </material>
    </visual>
    <collision>
      <origin rpy="0 0 0" xyz="0 0 0"/>
      <geometry>
        <mesh filename="./meshes/kortex_description/arms/gen3/7dof/meshes/shoulder_link.STL"/>
      </geometry>
    </collision>
  </link>
  <joint name="left_kinova_arm_joint_1" type="continuous">
    <origin rpy="3.1416 2.7629E-18 -4.9305E-36" xyz="0 0 0.15643"/>
    <parent link="left_kinova_arm_base_link"/>
    <child link="left_kinova_arm_shoulder_link"/>
    <axis xyz="0 0 1"/>
    <limit effort="39" velocity="1.3963"/>
  </joint>
  <link name="left_kinova_arm_half_arm_1_link">
    <inertial>
      <origin rpy="0 0 0" xyz="-4.4E-05 -0.09958 -0.013278"/>
      <mass value="1.1636"/>
      <inertia ixx="0.011088" ixy="5E-06" ixz="0" iyy="0.001072" iyz="-0.000691" izz="0.011255"/>
    </inertial>
    <visual>
      <origin rpy="0 0 0" xyz="0 0 0"/>
      <geometry>
        <mesh filename="./meshes/kortex_description/arms/gen3/7dof/meshes/half_arm_1_link.STL"/>
      </geometry>
      <material name="">
        <color rgba="0.75294 0.75294 0.75294 1"/>
      </material>
    </visual>
    <collision>
      <origin rpy="0 0 0" xyz="0 0 0"/>
      <geometry>
        <mesh filename="./meshes/kortex_description/arms/gen3/7dof/meshes/half_arm_1_link.STL"/>
      </geometry>
    </collision>
  </link>
  <joint name="left_kinova_arm_joint_2" type="revolute">
    <origin rpy="1.5708 2.1343E-17 -1.1102E-16" xyz="0 0.005375 -0.12838"/>
    <parent link="left_kinova_arm_shoulder_link"/>
    <child link="left_kinova_arm_half_arm_1_link"/>
    <axis xyz="0 0 1"/>
    <limit effort="39" lower="-2.24" upper="2.24" velocity="1.3963"/>
  </joint>
  <link name="left_kinova_arm_half_arm_2_link">
    <inertial>
      <origin rpy="0 0 0" xyz="-4.4E-05 -0.006641 -0.117892"/>
      <mass value="1.1636"/>
      <inertia ixx="0.010932" ixy="0" ixz="-7E-06" iyy="0.011127" iyz="0.000606" izz="0.001043"/>
    </inertial>
    <visual>
      <origin rpy="0 0 0" xyz="0 0 0"/>
      <geometry>
        <mesh filename="./meshes/kortex_description/arms/gen3/7dof/meshes/half_arm_2_link.STL"/>
      </geometry>
      <material name="">
        <color rgba="0.75294 0.75294 0.75294 1"/>
      </material>
    </visual>
    <collision>
      <origin rpy="0 0 0" xyz="0 0 0"/>
      <geometry>
        <mesh filename="./meshes/kortex_description/arms/gen3/7dof/meshes/half_arm_2_link.STL"/>
      </geometry>
    </collision>
  </link>
  <joint name="left_kinova_arm_joint_3" type="continuous">
    <origin rpy="-1.5708 1.2326E-32 -2.9122E-16" xyz="0 -0.21038 -0.006375"/>
    <parent link="left_kinova_arm_half_arm_1_link"/>
    <child link="left_kinova_arm_half_arm_2_link"/>
    <axis xyz="0 0 1"/>
    <limit effort="39" velocity="1.3963"/>
  </joint>
  <link name="left_kinova_arm_forearm_link">
    <inertial>
      <origin rpy="0 0 0" xyz="-1.8E-05 -0.075478 -0.015006"/>
      <mass value="0.9302"/>
      <inertia ixx="0.008147" ixy="-1E-06" ixz="0" iyy="0.000631" iyz="-0.0005" izz="0.008316"/>
    </inertial>
    <visual>
      <origin rpy="0 0 0" xyz="0 0 0"/>
      <geometry>
        <mesh filename="./meshes/kortex_description/arms/gen3/7dof/meshes/forearm_link.STL"/>
      </geometry>
      <material name="">
        <color rgba="0.75294 0.75294 0.75294 1"/>
      </material>
    </visual>
    <collision>
      <origin rpy="0 0 0" xyz="0 0 0"/>
      <geometry>
        <mesh filename="./meshes/kortex_description/arms/gen3/7dof/meshes/forearm_link.STL"/>
      </geometry>
    </collision>
  </link>
  <joint name="left_kinova_arm_joint_4" type="revolute">
    <origin rpy="1.5708 -6.6954E-17 -1.6653E-16" xyz="0 0.006375 -0.21038"/>
    <parent link="left_kinova_arm_half_arm_2_link"/>
    <child link="left_kinova_arm_forearm_link"/>
    <axis xyz="0 0 1"/>
    <limit effort="39" lower="-2.57" upper="2.57" velocity="1.3963"/>
  </joint>
  <link name="left_kinova_arm_spherical_wrist_1_link">
    <inertial>
      <origin rpy="0 0 0" xyz="1E-06 -0.009432 -0.063883"/>
      <mass value="0.6781"/>
      <inertia ixx="0.001596" ixy="0" ixz="0" iyy="0.001607" iyz="0.000256" izz="0.000399"/>
    </inertial>
    <visual>
      <origin rpy="0 0 0" xyz="0 0 0"/>
      <geometry>
        <mesh filename="./meshes/kortex_description/arms/gen3/7dof/meshes/spherical_wrist_1_link.STL"/>
      </geometry>
      <material name="">
        <color rgba="0.75294 0.75294 0.75294 1"/>
      </material>
    </visual>
    <collision>
      <origin rpy="0 0 0" xyz="0 0 0"/>
      <geometry>
        <mesh filename="./meshes/kortex_description/arms/gen3/7dof/meshes/spherical_wrist_1_link.STL"/>
      </geometry>
    </collision>
  </link>
  <joint name="left_kinova_arm_joint_5" type="continuous">
    <origin rpy="-1.5708 2.2204E-16 -6.373E-17" xyz="0 -0.20843 -0.006375"/>
    <parent link="left_kinova_arm_forearm_link"/>
    <child link="left_kinova_arm_spherical_wrist_1_link"/>
    <axis xyz="0 0 1"/>
    <limit effort="9" velocity="1.2218"/>
  </joint>
  <link name="left_kinova_arm_spherical_wrist_2_link">
    <inertial>
      <origin rpy="0 0 0" xyz="1E-06 -0.045483 -0.00965"/>
      <mass value="0.6781"/>
      <inertia ixx="0.001641" ixy="0" ixz="0" iyy="0.00041" iyz="-0.000278" izz="0.001641"/>
    </inertial>
    <visual>
      <origin rpy="0 0 0" xyz="0 0 0"/>
      <geometry>
        <mesh filename="./meshes/kortex_description/arms/gen3/7dof/meshes/spherical_wrist_2_link.STL"/>
      </geometry>
      <material name="">
        <color rgba="0.75294 0.75294 0.75294 1"/>
      </material>
    </visual>
    <collision>
      <origin rpy="0 0 0" xyz="0 0 0"/>
      <geometry>
        <mesh filename="./meshes/kortex_description/arms/gen3/7dof/meshes/spherical_wrist_2_link.STL"/>
      </geometry>
    </collision>
  </link>
  <joint name="left_kinova_arm_joint_6" type="revolute">
    <origin rpy="1.5708 9.2076E-28 -8.2157E-15" xyz="0 0.00017505 -0.10593"/>
    <parent link="left_kinova_arm_spherical_wrist_1_link"/>
    <child link="left_kinova_arm_spherical_wrist_2_link"/>
    <axis xyz="0 0 1"/>
    <limit effort="9" lower="-2.09" upper="2.09" velocity="1.2218"/>
  </joint>
  <link name="left_kinova_arm_bracelet_link">
    <inertial>
      <origin rpy="0 0 0" xyz="0.000281 0.011402 -0.029798"/>
      <mass value="0.5"/>
      <inertia ixx="0.000587" ixy="3E-06" ixz="3E-06" iyy="0.000369" iyz="-0.000118" izz="0.000609"/>
    </inertial>
    <visual>
      <origin rpy="0 0 0" xyz="0 0 0"/>
      <geometry>
        <mesh filename="./meshes/kortex_description/arms/gen3/7dof/meshes/bracelet_with_vision_link.STL"/>
      </geometry>
      <material name="">
        <color rgba="0.75294 0.75294 0.75294 1"/>
      </material>
    </visual>
    <collision>
      <origin rpy="0 0 0" xyz="0 0 0"/>
      <geometry>
        <mesh filename="./meshes/kortex_description/arms/gen3/7dof/meshes/bracelet_with_vision_link.STL"/>
      </geometry>
    </collision>
  </link>
  <joint name="left_kinova_arm_joint_7" type="continuous">
    <origin rpy="-1.5708 -5.5511E-17 9.6396E-17" xyz="0 -0.10593 -0.00017505"/>
    <parent link="left_kinova_arm_spherical_wrist_2_link"/>
    <child link="left_kinova_arm_bracelet_link"/>
    <axis xyz="0 0 1"/>
    <limit effort="9" velocity="1.2218"/>
  </joint>
  <link name="left_kinova_arm_end_effector_link"/>
  <joint name="left_kinova_arm_end_effector" type="fixed">
    <origin rpy="3.14159265358979 1.09937075168372E-32 0" xyz="0 0 -0.0615250000000001"/>
    <parent link="left_kinova_arm_bracelet_link"/>
    <child link="left_kinova_arm_end_effector_link"/>
    <axis xyz="0 0 0"/>
  </joint>
  <link name="left_kinova_arm_camera_link"/>
  <joint name="left_kinova_arm_camera_module" type="fixed">
    <origin rpy="3.14159265358979 3.14159265358979 0" xyz="0 0.05639 -0.00305"/>
    <parent link="left_kinova_arm_end_effector_link"/>
    <child link="left_kinova_arm_camera_link"/>
  </joint>
  <link name="left_kinova_arm_camera_depth_frame"/>
  <joint name="left_kinova_arm_depth_module" type="fixed">
    <origin rpy="3.14159265358979 3.14159265358979 0" xyz="0.0275 0.066 -0.00305"/>
    <parent link="left_kinova_arm_end_effector_link"/>
    <child link="left_kinova_arm_camera_depth_frame"/>
  </joint>
  <link name="left_kinova_arm_camera_color_frame"/>
  <joint name="left_kinova_arm_color_module" type="fixed">
    <origin rpy="3.14159265358979 3.14159265358979 0" xyz="0 0.05639 -0.00305"/>
    <parent link="left_kinova_arm_end_effector_link"/>
    <child link="left_kinova_arm_camera_color_frame"/>
  </joint>
  <!-- This line was removed by Kinova because we replaced the transmission file with our own 
    <xacro:include filename="$(find robotiq_2f_85_gripper_visualization)/urdf/robotiq_arg2f_transmission.xacro" /> -->
  <!-- Tool frame used by the arm -->
  <link name="left_kinova_arm_tool_frame"/>
  <joint name="left_kinova_arm_tool_frame_joint" type="fixed">
    <origin rpy="0 0 0" xyz="0 0 0.120"/>
    <parent link="left_kinova_arm_end_effector_link"/>
    <child link="left_kinova_arm_tool_frame"/>
    <axis xyz="0 0 0"/>
  </joint>
  <!-- This joint was added by Kinova -->
  <joint name="left_kinova_arm_gripper_base_joint" type="fixed">
    <parent link="left_kinova_arm_end_effector_link"/>
    <child link="left_kinova_arm_robotiq_arg2f_base_link"/>
    <origin rpy="0.0 0.0 1.57" xyz="0.0 0.0 0.0"/>
  </joint>
  <link name="left_kinova_arm_robotiq_arg2f_base_link">
    <inertial>
      <origin rpy="0 0 0" xyz="8.625E-08 -4.6583E-06 0.03145"/>
      <mass value="0.22652"/>
      <inertia ixx="0.00020005" ixy="-4.2442E-10" ixz="-2.9069E-10" iyy="0.00017832" iyz="-3.4402E-08" izz="0.00013478"/>
    </inertial>
    <visual>
      <origin rpy="0 0 0" xyz="0 0 0"/>
      <geometry>
        <!-- The stl file doesn't show well in Gazebo so we're using the STL instead -->
        <!-- <mesh filename="./meshes/kortex_description/grippers/robotiq_2f_85/meshes/visual/robotiq_arg2f_85_base_link.stl" scale="0.001 0.001 0.001"/> -->
        <mesh filename="./meshes/kortex_description/grippers/robotiq_2f_85/meshes/collision/robotiq_arg2f_base_link.stl"/>
      </geometry>
      <material name="">
        <color rgba="0.1 0.1 0.1 1"/>
      </material>
    </visual>
    <collision>
      <origin rpy="0 0 0" xyz="0 0 0"/>
      <geometry>
        <mesh filename="./meshes/kortex_description/grippers/robotiq_2f_85/meshes/collision/robotiq_arg2f_base_link.stl"/>
      </geometry>
    </collision>
  </link>
  <gazebo reference="left_kinova_arm_robotiq_arg2f_base_link">
    <material>Gazebo/Black</material>
  </gazebo>
  <link name="left_kinova_arm_left_outer_knuckle">
    <inertial>
      <origin rpy="0 0 0" xyz="-0.000200000000003065 0.0199435877845359 0.0292245259211331"/>
      <mass value="0.00853198276973456"/>
      <inertia ixx="2.89328108496468E-06" ixy="-1.57935047237397E-19" ixz="-1.93980378593255E-19" iyy="1.86719750325683E-06" iyz="-1.21858577871576E-06" izz="1.21905238907251E-06"/>
    </inertial>
    <visual>
      <origin rpy="0 0 0" xyz="0 0 0"/>
      <geometry>
        <mesh filename="./meshes/kortex_description/grippers/robotiq_2f_85/meshes/visual/robotiq_arg2f_85_outer_knuckle.stl" scale="0.001 0.001 0.001"/>
      </geometry>
      <material name="">
        <color rgba="0.792156862745098 0.819607843137255 0.933333333333333 1"/>
      </material>
    </visual>
    <collision>
      <origin rpy="0 0 0" xyz="0 0 0"/>
      <geometry>
        <mesh filename="./meshes/kortex_description/grippers/robotiq_2f_85/meshes/collision/robotiq_arg2f_85_outer_knuckle.stl" scale="0.001 0.001 0.001"/>
      </geometry>
    </collision>
  </link>
  <link name="left_kinova_arm_left_outer_finger">
    <inertial>
      <origin rpy="0 0 0" xyz="0.00030115855001899 0.0373907951953854 -0.0208027427000385"/>
      <mass value="0.022614240507152"/>
      <inertia ixx="1.52518312458174E-05" ixy="9.76583423954399E-10" ixz="-5.43838577022588E-10" iyy="6.17694243867776E-06" iyz="6.78636130740228E-06" izz="1.16494917907219E-05"/>
    </inertial>
    <visual>
      <origin rpy="0 0 0" xyz="0 0 0"/>
      <geometry>
        <mesh filename="./meshes/kortex_description/grippers/robotiq_2f_85/meshes/visual/robotiq_arg2f_85_outer_finger.stl" scale="0.001 0.001 0.001"/>
      </geometry>
      <material name="">
        <color rgba="0.1 0.1 0.1 1"/>
      </material>
    </visual>
    <collision>
      <origin rpy="0 0 0" xyz="0 0 0"/>
      <geometry>
        <mesh filename="./meshes/kortex_description/grippers/robotiq_2f_85/meshes/collision/robotiq_arg2f_85_outer_finger.stl" scale="0.001 0.001 0.001"/>
      </geometry>
    </collision>
  </link>
  <link name="left_kinova_arm_left_inner_finger">
    <inertial>
      <origin rpy="0 0 0" xyz="0.000299999999999317 0.0160078233491243 -0.0136945669206257"/>
      <mass value="0.0104003125914103"/>
      <inertia ixx="2.71909453810972E-06" ixy="1.35402465472579E-21" ixz="-7.1817349065269E-22" iyy="7.69100314106116E-07" iyz="6.74715432769696E-07" izz="2.30315190420171E-06"/>
    </inertial>
    <visual>
      <origin rpy="0 0 0" xyz="0 0 0"/>
      <geometry>
        <mesh filename="./meshes/kortex_description/grippers/robotiq_2f_85/meshes/visual/robotiq_arg2f_85_inner_finger.stl" scale="0.001 0.001 0.001"/>
      </geometry>
      <material name="">
        <color rgba="0.1 0.1 0.1 1"/>
      </material>
    </visual>
    <collision>
      <origin rpy="0 0 0" xyz="0 0 0"/>
      <geometry>
        <mesh filename="./meshes/kortex_description/grippers/robotiq_2f_85/meshes/collision/robotiq_arg2f_85_inner_finger.stl" scale="0.001 0.001 0.001"/>
      </geometry>
    </collision>
  </link>
  <link name="left_kinova_arm_left_inner_finger_pad">
    <visual>
      <origin rpy="0 0 0" xyz="0 0 0"/>
      <geometry>
        <box size="0.022 0.00635 0.0375"/>
      </geometry>
      <material name="">
        <color rgba="0.9 0.9 0.9 1"/>
      </material>
    </visual>
    <collision>
      <origin rpy="0 0 0" xyz="0 0 0"/>
      <geometry>
        <box size="0.022 0.00635 0.0375"/>
      </geometry>
      <material name="">
        <color rgba="0.9 0.0 0.0 1"/>
      </material>
    </collision>
  </link>
  <link name="left_kinova_arm_left_inner_knuckle">
    <inertial>
      <origin rpy="0 0 0" xyz="0.000123011831763771 0.0507850843201817 0.00103968640075166"/>
      <mass value="0.0271177346495152"/>
      <inertia ixx="2.61910379223783E-05" ixy="-2.43616858946494E-07" ixz="-6.37789906117123E-09" iyy="2.8270243746167E-06" iyz="-5.37200748039765E-07" izz="2.83695868220296E-05"/>
    </inertial>
    <visual>
      <origin rpy="0 0 0" xyz="0 0 0"/>
      <geometry>
        <mesh filename="./meshes/kortex_description/grippers/robotiq_2f_85/meshes/visual/robotiq_arg2f_85_inner_knuckle.stl" scale="0.001 0.001 0.001"/>
      </geometry>
      <material name="">
        <color rgba="0.1 0.1 0.1 1"/>
      </material>
    </visual>
    <collision>
      <origin rpy="0 0 0" xyz="0 0 0"/>
      <geometry>
        <mesh filename="./meshes/kortex_description/grippers/robotiq_2f_85/meshes/collision/robotiq_arg2f_85_inner_knuckle.stl" scale="0.001 0.001 0.001"/>
      </geometry>
    </collision>
  </link>
  <link name="left_kinova_arm_right_outer_knuckle">
    <inertial>
      <origin rpy="0 0 0" xyz="-0.000200000000003065 0.0199435877845359 0.0292245259211331"/>
      <mass value="0.00853198276973456"/>
      <inertia ixx="2.89328108496468E-06" ixy="-1.57935047237397E-19" ixz="-1.93980378593255E-19" iyy="1.86719750325683E-06" iyz="-1.21858577871576E-06" izz="1.21905238907251E-06"/>
    </inertial>
    <visual>
      <origin rpy="0 0 0" xyz="0 0 0"/>
      <geometry>
        <mesh filename="./meshes/kortex_description/grippers/robotiq_2f_85/meshes/visual/robotiq_arg2f_85_outer_knuckle.stl" scale="0.001 0.001 0.001"/>
      </geometry>
      <material name="">
        <color rgba="0.792156862745098 0.819607843137255 0.933333333333333 1"/>
      </material>
    </visual>
    <collision>
      <origin rpy="0 0 0" xyz="0 0 0"/>
      <geometry>
        <mesh filename="./meshes/kortex_description/grippers/robotiq_2f_85/meshes/collision/robotiq_arg2f_85_outer_knuckle.stl" scale="0.001 0.001 0.001"/>
      </geometry>
    </collision>
  </link>
  <link name="left_kinova_arm_right_outer_finger">
    <inertial>
      <origin rpy="0 0 0" xyz="0.00030115855001899 0.0373907951953854 -0.0208027427000385"/>
      <mass value="0.022614240507152"/>
      <inertia ixx="1.52518312458174E-05" ixy="9.76583423954399E-10" ixz="-5.43838577022588E-10" iyy="6.17694243867776E-06" iyz="6.78636130740228E-06" izz="1.16494917907219E-05"/>
    </inertial>
    <visual>
      <origin rpy="0 0 0" xyz="0 0 0"/>
      <geometry>
        <mesh filename="./meshes/kortex_description/grippers/robotiq_2f_85/meshes/visual/robotiq_arg2f_85_outer_finger.stl" scale="0.001 0.001 0.001"/>
      </geometry>
      <material name="">
        <color rgba="0.1 0.1 0.1 1"/>
      </material>
    </visual>
    <collision>
      <origin rpy="0 0 0" xyz="0 0 0"/>
      <geometry>
        <mesh filename="./meshes/kortex_description/grippers/robotiq_2f_85/meshes/collision/robotiq_arg2f_85_outer_finger.stl" scale="0.001 0.001 0.001"/>
      </geometry>
    </collision>
  </link>
  <link name="left_kinova_arm_right_inner_finger">
    <inertial>
      <origin rpy="0 0 0" xyz="0.000299999999999317 0.0160078233491243 -0.0136945669206257"/>
      <mass value="0.0104003125914103"/>
      <inertia ixx="2.71909453810972E-06" ixy="1.35402465472579E-21" ixz="-7.1817349065269E-22" iyy="7.69100314106116E-07" iyz="6.74715432769696E-07" izz="2.30315190420171E-06"/>
    </inertial>
    <visual>
      <origin rpy="0 0 0" xyz="0 0 0"/>
      <geometry>
        <mesh filename="./meshes/kortex_description/grippers/robotiq_2f_85/meshes/visual/robotiq_arg2f_85_inner_finger.stl" scale="0.001 0.001 0.001"/>
      </geometry>
      <material name="">
        <color rgba="0.1 0.1 0.1 1"/>
      </material>
    </visual>
    <collision>
      <origin rpy="0 0 0" xyz="0 0 0"/>
      <geometry>
        <mesh filename="./meshes/kortex_description/grippers/robotiq_2f_85/meshes/collision/robotiq_arg2f_85_inner_finger.stl" scale="0.001 0.001 0.001"/>
      </geometry>
    </collision>
  </link>
  <link name="left_kinova_arm_right_inner_finger_pad">
    <visual>
      <origin rpy="0 0 0" xyz="0 0 0"/>
      <geometry>
        <box size="0.022 0.00635 0.0375"/>
      </geometry>
      <material name="">
        <color rgba="0.9 0.9 0.9 1"/>
      </material>
    </visual>
    <collision>
      <origin rpy="0 0 0" xyz="0 0 0"/>
      <geometry>
        <box size="0.022 0.00635 0.0375"/>
      </geometry>
      <material name="">
        <color rgba="0.9 0.0 0.0 1"/>
      </material>
    </collision>
  </link>
  <link name="left_kinova_arm_right_inner_knuckle">
    <inertial>
      <origin rpy="0 0 0" xyz="0.000123011831763771 0.0507850843201817 0.00103968640075166"/>
      <mass value="0.0271177346495152"/>
      <inertia ixx="2.61910379223783E-05" ixy="-2.43616858946494E-07" ixz="-6.37789906117123E-09" iyy="2.8270243746167E-06" iyz="-5.37200748039765E-07" izz="2.83695868220296E-05"/>
    </inertial>
    <visual>
      <origin rpy="0 0 0" xyz="0 0 0"/>
      <geometry>
        <mesh filename="./meshes/kortex_description/grippers/robotiq_2f_85/meshes/visual/robotiq_arg2f_85_inner_knuckle.stl" scale="0.001 0.001 0.001"/>
      </geometry>
      <material name="">
        <color rgba="0.1 0.1 0.1 1"/>
      </material>
    </visual>
    <collision>
      <origin rpy="0 0 0" xyz="0 0 0"/>
      <geometry>
        <mesh filename="./meshes/kortex_description/grippers/robotiq_2f_85/meshes/collision/robotiq_arg2f_85_inner_knuckle.stl" scale="0.001 0.001 0.001"/>
      </geometry>
    </collision>
  </link>
  <joint name="left_kinova_arm_finger_joint" type="revolute">
    <origin rpy="0 0 3.141592653589793" xyz="0 -0.0306011 0.054904"/>
    <parent link="left_kinova_arm_robotiq_arg2f_base_link"/>
    <child link="left_kinova_arm_left_outer_knuckle"/>
    <axis xyz="1 0 0"/>
    <limit effort="1000" lower="0" upper="0.8" velocity="2.0"/>
  </joint>
  <joint name="left_kinova_arm_left_outer_finger_joint" type="fixed">
    <origin rpy="0 0 0" xyz="0 0.0315 -0.0041"/>
    <parent link="left_kinova_arm_left_outer_knuckle"/>
    <child link="left_kinova_arm_left_outer_finger"/>
    <axis xyz="1 0 0"/>
  </joint>
  <joint name="left_kinova_arm_left_inner_knuckle_joint" type="revolute">
    <!-- <origin xyz="0 ${reflect * -0.0127} 0.06142" rpy="${pi / 2 + .725} 0 ${(reflect - 1) * pi / 2}" /> -->
    <origin rpy="0 0 3.141592653589793" xyz="0 -0.0127 0.06142"/>
    <parent link="left_kinova_arm_robotiq_arg2f_base_link"/>
    <child link="left_kinova_arm_left_inner_knuckle"/>
    <axis xyz="1 0 0"/>
    <limit effort="1000" lower="0" upper="0.8757" velocity="2.0"/>
    <mimic joint="left_kinova_arm_finger_joint" multiplier="1" offset="0"/>
  </joint>
  <joint name="left_kinova_arm_left_inner_finger_joint" type="revolute">
    <origin rpy="0 0 0" xyz="0 0.0061 0.0471"/>
    <parent link="left_kinova_arm_left_outer_finger"/>
    <child link="left_kinova_arm_left_inner_finger"/>
    <axis xyz="1 0 0"/>
    <limit effort="1000" lower="-0.8757" upper="0.8757" velocity="2.0"/>
    <mimic joint="left_kinova_arm_finger_joint" multiplier="-1" offset="0"/>
  </joint>
  <joint name="left_kinova_arm_left_inner_finger_pad_joint" type="fixed">
    <origin rpy="0 0 0" xyz="0 -0.0220203446692936 0.03242"/>
    <parent link="left_kinova_arm_left_inner_finger"/>
    <child link="left_kinova_arm_left_inner_finger_pad"/>
    <axis xyz="0 0 1"/>
  </joint>
  <joint name="left_kinova_arm_right_outer_knuckle_joint" type="revolute">
    <origin rpy="0 0 0" xyz="0 0.0306011 0.054904"/>
    <parent link="left_kinova_arm_robotiq_arg2f_base_link"/>
    <child link="left_kinova_arm_right_outer_knuckle"/>
    <axis xyz="1 0 0"/>
    <limit effort="1000" lower="0" upper="0.81" velocity="2.0"/>
    <mimic joint="left_kinova_arm_finger_joint" multiplier="1" offset="0"/>
  </joint>
  <joint name="left_kinova_arm_right_outer_finger_joint" type="fixed">
    <origin rpy="0 0 0" xyz="0 0.0315 -0.0041"/>
    <parent link="left_kinova_arm_right_outer_knuckle"/>
    <child link="left_kinova_arm_right_outer_finger"/>
    <axis xyz="1 0 0"/>
  </joint>
  <joint name="left_kinova_arm_right_inner_knuckle_joint" type="revolute">
    <!-- <origin xyz="0 ${reflect * -0.0127} 0.06142" rpy="${pi / 2 + .725} 0 ${(reflect - 1) * pi / 2}" /> -->
    <origin rpy="0 0 0.0" xyz="0 0.0127 0.06142"/>
    <parent link="left_kinova_arm_robotiq_arg2f_base_link"/>
    <child link="left_kinova_arm_right_inner_knuckle"/>
    <axis xyz="1 0 0"/>
    <limit effort="1000" lower="0" upper="0.8757" velocity="2.0"/>
    <mimic joint="left_kinova_arm_finger_joint" multiplier="1" offset="0"/>
  </joint>
  <joint name="left_kinova_arm_right_inner_finger_joint" type="revolute">
    <origin rpy="0 0 0" xyz="0 0.0061 0.0471"/>
    <parent link="left_kinova_arm_right_outer_finger"/>
    <child link="left_kinova_arm_right_inner_finger"/>
    <axis xyz="1 0 0"/>
    <limit effort="1000" lower="-0.8757" upper="0.8757" velocity="2.0"/>
    <mimic joint="left_kinova_arm_finger_joint" multiplier="-1" offset="0"/>
  </joint>
  <joint name="left_kinova_arm_right_inner_finger_pad_joint" type="fixed">
    <origin rpy="0 0 0" xyz="0 -0.0220203446692936 0.03242"/>
    <parent link="left_kinova_arm_right_inner_finger"/>
    <child link="left_kinova_arm_right_inner_finger_pad"/>
    <axis xyz="0 0 1"/>
  </joint>
  <!-- Transmissions are loaded in the generic kortex xacro when simulation is enabled -->
  <!-- <xacro:robotiq_arg2f_transmission prefix="${prefix}"/> -->
  <!-- Run the macros -->
  <link name="right_kinova_arm_base_link">
    <inertial>
      <origin rpy="0 0 0" xyz="-0.000648 -0.000166 0.084487"/>
      <mass value="1.697"/>
      <inertia ixx="0.004622" ixy="9E-06" ixz="6E-05" iyy="0.004495" iyz="9E-06" izz="0.002079"/>
    </inertial>
    <visual>
      <origin rpy="0 0 0" xyz="0 0 0"/>
      <geometry>
        <mesh filename="./meshes/kortex_description/arms/gen3/7dof/meshes/base_link.STL"/>
      </geometry>
      <material name="">
        <color rgba="0.75294 0.75294 0.75294 1"/>
      </material>
    </visual>
    <collision>
      <origin rpy="0 0 0" xyz="0 0 0"/>
      <geometry>
        <mesh filename="./meshes/kortex_description/arms/gen3/7dof/meshes/base_link.STL"/>
      </geometry>
    </collision>
  </link>
  <link name="right_kinova_arm_shoulder_link">
    <inertial>
      <origin rpy="0 0 0" xyz="-2.3E-05 -0.010364 -0.07336"/>
      <mass value="1.3773"/>
      <inertia ixx="0.00457" ixy="1E-06" ixz="2E-06" iyy="0.004831" iyz="0.000448" izz="0.001409"/>
    </inertial>
    <visual>
      <origin rpy="0 0 0" xyz="0 0 0"/>
      <geometry>
        <mesh filename="./meshes/kortex_description/arms/gen3/7dof/meshes/shoulder_link.STL"/>
      </geometry>
      <material name="">
        <color rgba="0.75294 0.75294 0.75294 1"/>
      </material>
    </visual>
    <collision>
      <origin rpy="0 0 0" xyz="0 0 0"/>
      <geometry>
        <mesh filename="./meshes/kortex_description/arms/gen3/7dof/meshes/shoulder_link.STL"/>
      </geometry>
    </collision>
  </link>
  <joint name="right_kinova_arm_joint_1" type="continuous">
    <origin rpy="3.1416 2.7629E-18 -4.9305E-36" xyz="0 0 0.15643"/>
    <parent link="right_kinova_arm_base_link"/>
    <child link="right_kinova_arm_shoulder_link"/>
    <axis xyz="0 0 1"/>
    <limit effort="39" velocity="1.3963"/>
  </joint>
  <link name="right_kinova_arm_half_arm_1_link">
    <inertial>
      <origin rpy="0 0 0" xyz="-4.4E-05 -0.09958 -0.013278"/>
      <mass value="1.1636"/>
      <inertia ixx="0.011088" ixy="5E-06" ixz="0" iyy="0.001072" iyz="-0.000691" izz="0.011255"/>
    </inertial>
    <visual>
      <origin rpy="0 0 0" xyz="0 0 0"/>
      <geometry>
        <mesh filename="./meshes/kortex_description/arms/gen3/7dof/meshes/half_arm_1_link.STL"/>
      </geometry>
      <material name="">
        <color rgba="0.75294 0.75294 0.75294 1"/>
      </material>
    </visual>
    <collision>
      <origin rpy="0 0 0" xyz="0 0 0"/>
      <geometry>
        <mesh filename="./meshes/kortex_description/arms/gen3/7dof/meshes/half_arm_1_link.STL"/>
      </geometry>
    </collision>
  </link>
  <joint name="right_kinova_arm_joint_2" type="revolute">
    <origin rpy="1.5708 2.1343E-17 -1.1102E-16" xyz="0 0.005375 -0.12838"/>
    <parent link="right_kinova_arm_shoulder_link"/>
    <child link="right_kinova_arm_half_arm_1_link"/>
    <axis xyz="0 0 1"/>
    <limit effort="39" lower="-2.24" upper="2.24" velocity="1.3963"/>
  </joint>
  <link name="right_kinova_arm_half_arm_2_link">
    <inertial>
      <origin rpy="0 0 0" xyz="-4.4E-05 -0.006641 -0.117892"/>
      <mass value="1.1636"/>
      <inertia ixx="0.010932" ixy="0" ixz="-7E-06" iyy="0.011127" iyz="0.000606" izz="0.001043"/>
    </inertial>
    <visual>
      <origin rpy="0 0 0" xyz="0 0 0"/>
      <geometry>
        <mesh filename="./meshes/kortex_description/arms/gen3/7dof/meshes/half_arm_2_link.STL"/>
      </geometry>
      <material name="">
        <color rgba="0.75294 0.75294 0.75294 1"/>
      </material>
    </visual>
    <collision>
      <origin rpy="0 0 0" xyz="0 0 0"/>
      <geometry>
        <mesh filename="./meshes/kortex_description/arms/gen3/7dof/meshes/half_arm_2_link.STL"/>
      </geometry>
    </collision>
  </link>
  <joint name="right_kinova_arm_joint_3" type="continuous">
    <origin rpy="-1.5708 1.2326E-32 -2.9122E-16" xyz="0 -0.21038 -0.006375"/>
    <parent link="right_kinova_arm_half_arm_1_link"/>
    <child link="right_kinova_arm_half_arm_2_link"/>
    <axis xyz="0 0 1"/>
    <limit effort="39" velocity="1.3963"/>
  </joint>
  <link name="right_kinova_arm_forearm_link">
    <inertial>
      <origin rpy="0 0 0" xyz="-1.8E-05 -0.075478 -0.015006"/>
      <mass value="0.9302"/>
      <inertia ixx="0.008147" ixy="-1E-06" ixz="0" iyy="0.000631" iyz="-0.0005" izz="0.008316"/>
    </inertial>
    <visual>
      <origin rpy="0 0 0" xyz="0 0 0"/>
      <geometry>
        <mesh filename="./meshes/kortex_description/arms/gen3/7dof/meshes/forearm_link.STL"/>
      </geometry>
      <material name="">
        <color rgba="0.75294 0.75294 0.75294 1"/>
      </material>
    </visual>
    <collision>
      <origin rpy="0 0 0" xyz="0 0 0"/>
      <geometry>
        <mesh filename="./meshes/kortex_description/arms/gen3/7dof/meshes/forearm_link.STL"/>
      </geometry>
    </collision>
  </link>
  <joint name="right_kinova_arm_joint_4" type="revolute">
    <origin rpy="1.5708 -6.6954E-17 -1.6653E-16" xyz="0 0.006375 -0.21038"/>
    <parent link="right_kinova_arm_half_arm_2_link"/>
    <child link="right_kinova_arm_forearm_link"/>
    <axis xyz="0 0 1"/>
    <limit effort="39" lower="-2.57" upper="2.57" velocity="1.3963"/>
  </joint>
  <link name="right_kinova_arm_spherical_wrist_1_link">
    <inertial>
      <origin rpy="0 0 0" xyz="1E-06 -0.009432 -0.063883"/>
      <mass value="0.6781"/>
      <inertia ixx="0.001596" ixy="0" ixz="0" iyy="0.001607" iyz="0.000256" izz="0.000399"/>
    </inertial>
    <visual>
      <origin rpy="0 0 0" xyz="0 0 0"/>
      <geometry>
        <mesh filename="./meshes/kortex_description/arms/gen3/7dof/meshes/spherical_wrist_1_link.STL"/>
      </geometry>
      <material name="">
        <color rgba="0.75294 0.75294 0.75294 1"/>
      </material>
    </visual>
    <collision>
      <origin rpy="0 0 0" xyz="0 0 0"/>
      <geometry>
        <mesh filename="./meshes/kortex_description/arms/gen3/7dof/meshes/spherical_wrist_1_link.STL"/>
      </geometry>
    </collision>
  </link>
  <joint name="right_kinova_arm_joint_5" type="continuous">
    <origin rpy="-1.5708 2.2204E-16 -6.373E-17" xyz="0 -0.20843 -0.006375"/>
    <parent link="right_kinova_arm_forearm_link"/>
    <child link="right_kinova_arm_spherical_wrist_1_link"/>
    <axis xyz="0 0 1"/>
    <limit effort="9" velocity="1.2218"/>
  </joint>
  <link name="right_kinova_arm_spherical_wrist_2_link">
    <inertial>
      <origin rpy="0 0 0" xyz="1E-06 -0.045483 -0.00965"/>
      <mass value="0.6781"/>
      <inertia ixx="0.001641" ixy="0" ixz="0" iyy="0.00041" iyz="-0.000278" izz="0.001641"/>
    </inertial>
    <visual>
      <origin rpy="0 0 0" xyz="0 0 0"/>
      <geometry>
        <mesh filename="./meshes/kortex_description/arms/gen3/7dof/meshes/spherical_wrist_2_link.STL"/>
      </geometry>
      <material name="">
        <color rgba="0.75294 0.75294 0.75294 1"/>
      </material>
    </visual>
    <collision>
      <origin rpy="0 0 0" xyz="0 0 0"/>
      <geometry>
        <mesh filename="./meshes/kortex_description/arms/gen3/7dof/meshes/spherical_wrist_2_link.STL"/>
      </geometry>
    </collision>
  </link>
  <joint name="right_kinova_arm_joint_6" type="revolute">
    <origin rpy="1.5708 9.2076E-28 -8.2157E-15" xyz="0 0.00017505 -0.10593"/>
    <parent link="right_kinova_arm_spherical_wrist_1_link"/>
    <child link="right_kinova_arm_spherical_wrist_2_link"/>
    <axis xyz="0 0 1"/>
    <limit effort="9" lower="-2.09" upper="2.09" velocity="1.2218"/>
  </joint>
  <link name="right_kinova_arm_bracelet_link">
    <inertial>
      <origin rpy="0 0 0" xyz="0.000281 0.011402 -0.029798"/>
      <mass value="0.5"/>
      <inertia ixx="0.000587" ixy="3E-06" ixz="3E-06" iyy="0.000369" iyz="-0.000118" izz="0.000609"/>
    </inertial>
    <visual>
      <origin rpy="0 0 0" xyz="0 0 0"/>
      <geometry>
        <mesh filename="./meshes/kortex_description/arms/gen3/7dof/meshes/bracelet_with_vision_link.STL"/>
      </geometry>
      <material name="">
        <color rgba="0.75294 0.75294 0.75294 1"/>
      </material>
    </visual>
    <collision>
      <origin rpy="0 0 0" xyz="0 0 0"/>
      <geometry>
        <mesh filename="./meshes/kortex_description/arms/gen3/7dof/meshes/bracelet_with_vision_link.STL"/>
      </geometry>
    </collision>
  </link>
  <joint name="right_kinova_arm_joint_7" type="continuous">
    <origin rpy="-1.5708 -5.5511E-17 9.6396E-17" xyz="0 -0.10593 -0.00017505"/>
    <parent link="right_kinova_arm_spherical_wrist_2_link"/>
    <child link="right_kinova_arm_bracelet_link"/>
    <axis xyz="0 0 1"/>
    <limit effort="9" velocity="1.2218"/>
  </joint>
  <link name="right_kinova_arm_end_effector_link"/>
  <joint name="right_kinova_arm_end_effector" type="fixed">
    <origin rpy="3.14159265358979 1.09937075168372E-32 0" xyz="0 0 -0.0615250000000001"/>
    <parent link="right_kinova_arm_bracelet_link"/>
    <child link="right_kinova_arm_end_effector_link"/>
    <axis xyz="0 0 0"/>
  </joint>
  <link name="right_kinova_arm_camera_link"/>
  <joint name="right_kinova_arm_camera_module" type="fixed">
    <origin rpy="3.14159265358979 3.14159265358979 0" xyz="0 0.05639 -0.00305"/>
    <parent link="right_kinova_arm_end_effector_link"/>
    <child link="right_kinova_arm_camera_link"/>
  </joint>
  <link name="right_kinova_arm_camera_depth_frame"/>
  <joint name="right_kinova_arm_depth_module" type="fixed">
    <origin rpy="3.14159265358979 3.14159265358979 0" xyz="0.0275 0.066 -0.00305"/>
    <parent link="right_kinova_arm_end_effector_link"/>
    <child link="right_kinova_arm_camera_depth_frame"/>
  </joint>
  <link name="right_kinova_arm_camera_color_frame"/>
  <joint name="right_kinova_arm_color_module" type="fixed">
    <origin rpy="3.14159265358979 3.14159265358979 0" xyz="0 0.05639 -0.00305"/>
    <parent link="right_kinova_arm_end_effector_link"/>
    <child link="right_kinova_arm_camera_color_frame"/>
  </joint>
  <!-- This line was removed by Kinova because we replaced the transmission file with our own 
    <xacro:include filename="$(find robotiq_2f_85_gripper_visualization)/urdf/robotiq_arg2f_transmission.xacro" /> -->
  <!-- Tool frame used by the arm -->
  <link name="right_kinova_arm_tool_frame"/>
  <joint name="right_kinova_arm_tool_frame_joint" type="fixed">
    <origin rpy="0 0 0" xyz="0 0 0.120"/>
    <parent link="right_kinova_arm_end_effector_link"/>
    <child link="right_kinova_arm_tool_frame"/>
    <axis xyz="0 0 0"/>
  </joint>
  <!-- This joint was added by Kinova -->
  <joint name="right_kinova_arm_gripper_base_joint" type="fixed">
    <parent link="right_kinova_arm_end_effector_link"/>
    <child link="right_kinova_arm_robotiq_arg2f_base_link"/>
    <origin rpy="0.0 0.0 1.57" xyz="0.0 0.0 0.0"/>
  </joint>
  <link name="right_kinova_arm_robotiq_arg2f_base_link">
    <inertial>
      <origin rpy="0 0 0" xyz="8.625E-08 -4.6583E-06 0.03145"/>
      <mass value="0.22652"/>
      <inertia ixx="0.00020005" ixy="-4.2442E-10" ixz="-2.9069E-10" iyy="0.00017832" iyz="-3.4402E-08" izz="0.00013478"/>
    </inertial>
    <visual>
      <origin rpy="0 0 0" xyz="0 0 0"/>
      <geometry>
        <!-- The stl file doesn't show well in Gazebo so we're using the STL instead -->
        <!-- <mesh filename="./meshes/kortex_description/grippers/robotiq_2f_85/meshes/visual/robotiq_arg2f_85_base_link.stl" scale="0.001 0.001 0.001"/> -->
        <mesh filename="./meshes/kortex_description/grippers/robotiq_2f_85/meshes/collision/robotiq_arg2f_base_link.stl"/>
      </geometry>
      <material name="">
        <color rgba="0.1 0.1 0.1 1"/>
      </material>
    </visual>
    <collision>
      <origin rpy="0 0 0" xyz="0 0 0"/>
      <geometry>
        <mesh filename="./meshes/kortex_description/grippers/robotiq_2f_85/meshes/collision/robotiq_arg2f_base_link.stl"/>
      </geometry>
    </collision>
  </link>
  <gazebo reference="right_kinova_arm_robotiq_arg2f_base_link">
    <material>Gazebo/Black</material>
  </gazebo>
  <link name="right_kinova_arm_left_outer_knuckle">
    <inertial>
      <origin rpy="0 0 0" xyz="-0.000200000000003065 0.0199435877845359 0.0292245259211331"/>
      <mass value="0.00853198276973456"/>
      <inertia ixx="2.89328108496468E-06" ixy="-1.57935047237397E-19" ixz="-1.93980378593255E-19" iyy="1.86719750325683E-06" iyz="-1.21858577871576E-06" izz="1.21905238907251E-06"/>
    </inertial>
    <visual>
      <origin rpy="0 0 0" xyz="0 0 0"/>
      <geometry>
        <mesh filename="./meshes/kortex_description/grippers/robotiq_2f_85/meshes/visual/robotiq_arg2f_85_outer_knuckle.stl" scale="0.001 0.001 0.001"/>
      </geometry>
      <material name="">
        <color rgba="0.792156862745098 0.819607843137255 0.933333333333333 1"/>
      </material>
    </visual>
    <collision>
      <origin rpy="0 0 0" xyz="0 0 0"/>
      <geometry>
        <mesh filename="./meshes/kortex_description/grippers/robotiq_2f_85/meshes/collision/robotiq_arg2f_85_outer_knuckle.stl" scale="0.001 0.001 0.001"/>
      </geometry>
    </collision>
  </link>
  <link name="right_kinova_arm_left_outer_finger">
    <inertial>
      <origin rpy="0 0 0" xyz="0.00030115855001899 0.0373907951953854 -0.0208027427000385"/>
      <mass value="0.022614240507152"/>
      <inertia ixx="1.52518312458174E-05" ixy="9.76583423954399E-10" ixz="-5.43838577022588E-10" iyy="6.17694243867776E-06" iyz="6.78636130740228E-06" izz="1.16494917907219E-05"/>
    </inertial>
    <visual>
      <origin rpy="0 0 0" xyz="0 0 0"/>
      <geometry>
        <mesh filename="./meshes/kortex_description/grippers/robotiq_2f_85/meshes/visual/robotiq_arg2f_85_outer_finger.stl" scale="0.001 0.001 0.001"/>
      </geometry>
      <material name="">
        <color rgba="0.1 0.1 0.1 1"/>
      </material>
    </visual>
    <collision>
      <origin rpy="0 0 0" xyz="0 0 0"/>
      <geometry>
        <mesh filename="./meshes/kortex_description/grippers/robotiq_2f_85/meshes/collision/robotiq_arg2f_85_outer_finger.stl" scale="0.001 0.001 0.001"/>
      </geometry>
    </collision>
  </link>
  <link name="right_kinova_arm_left_inner_finger">
    <inertial>
      <origin rpy="0 0 0" xyz="0.000299999999999317 0.0160078233491243 -0.0136945669206257"/>
      <mass value="0.0104003125914103"/>
      <inertia ixx="2.71909453810972E-06" ixy="1.35402465472579E-21" ixz="-7.1817349065269E-22" iyy="7.69100314106116E-07" iyz="6.74715432769696E-07" izz="2.30315190420171E-06"/>
    </inertial>
    <visual>
      <origin rpy="0 0 0" xyz="0 0 0"/>
      <geometry>
        <mesh filename="./meshes/kortex_description/grippers/robotiq_2f_85/meshes/visual/robotiq_arg2f_85_inner_finger.stl" scale="0.001 0.001 0.001"/>
      </geometry>
      <material name="">
        <color rgba="0.1 0.1 0.1 1"/>
      </material>
    </visual>
    <collision>
      <origin rpy="0 0 0" xyz="0 0 0"/>
      <geometry>
        <mesh filename="./meshes/kortex_description/grippers/robotiq_2f_85/meshes/collision/robotiq_arg2f_85_inner_finger.stl" scale="0.001 0.001 0.001"/>
      </geometry>
    </collision>
  </link>
  <link name="right_kinova_arm_left_inner_finger_pad">
    <visual>
      <origin rpy="0 0 0" xyz="0 0 0"/>
      <geometry>
        <box size="0.022 0.00635 0.0375"/>
      </geometry>
      <material name="">
        <color rgba="0.9 0.9 0.9 1"/>
      </material>
    </visual>
    <collision>
      <origin rpy="0 0 0" xyz="0 0 0"/>
      <geometry>
        <box size="0.022 0.00635 0.0375"/>
      </geometry>
      <material name="">
        <color rgba="0.9 0.0 0.0 1"/>
      </material>
    </collision>
  </link>
  <link name="right_kinova_arm_left_inner_knuckle">
    <inertial>
      <origin rpy="0 0 0" xyz="0.000123011831763771 0.0507850843201817 0.00103968640075166"/>
      <mass value="0.0271177346495152"/>
      <inertia ixx="2.61910379223783E-05" ixy="-2.43616858946494E-07" ixz="-6.37789906117123E-09" iyy="2.8270243746167E-06" iyz="-5.37200748039765E-07" izz="2.83695868220296E-05"/>
    </inertial>
    <visual>
      <origin rpy="0 0 0" xyz="0 0 0"/>
      <geometry>
        <mesh filename="./meshes/kortex_description/grippers/robotiq_2f_85/meshes/visual/robotiq_arg2f_85_inner_knuckle.stl" scale="0.001 0.001 0.001"/>
      </geometry>
      <material name="">
        <color rgba="0.1 0.1 0.1 1"/>
      </material>
    </visual>
    <collision>
      <origin rpy="0 0 0" xyz="0 0 0"/>
      <geometry>
        <mesh filename="./meshes/kortex_description/grippers/robotiq_2f_85/meshes/collision/robotiq_arg2f_85_inner_knuckle.stl" scale="0.001 0.001 0.001"/>
      </geometry>
    </collision>
  </link>
  <link name="right_kinova_arm_right_outer_knuckle">
    <inertial>
      <origin rpy="0 0 0" xyz="-0.000200000000003065 0.0199435877845359 0.0292245259211331"/>
      <mass value="0.00853198276973456"/>
      <inertia ixx="2.89328108496468E-06" ixy="-1.57935047237397E-19" ixz="-1.93980378593255E-19" iyy="1.86719750325683E-06" iyz="-1.21858577871576E-06" izz="1.21905238907251E-06"/>
    </inertial>
    <visual>
      <origin rpy="0 0 0" xyz="0 0 0"/>
      <geometry>
        <mesh filename="./meshes/kortex_description/grippers/robotiq_2f_85/meshes/visual/robotiq_arg2f_85_outer_knuckle.stl" scale="0.001 0.001 0.001"/>
      </geometry>
      <material name="">
        <color rgba="0.792156862745098 0.819607843137255 0.933333333333333 1"/>
      </material>
    </visual>
    <collision>
      <origin rpy="0 0 0" xyz="0 0 0"/>
      <geometry>
        <mesh filename="./meshes/kortex_description/grippers/robotiq_2f_85/meshes/collision/robotiq_arg2f_85_outer_knuckle.stl" scale="0.001 0.001 0.001"/>
      </geometry>
    </collision>
  </link>
  <link name="right_kinova_arm_right_outer_finger">
    <inertial>
      <origin rpy="0 0 0" xyz="0.00030115855001899 0.0373907951953854 -0.0208027427000385"/>
      <mass value="0.022614240507152"/>
      <inertia ixx="1.52518312458174E-05" ixy="9.76583423954399E-10" ixz="-5.43838577022588E-10" iyy="6.17694243867776E-06" iyz="6.78636130740228E-06" izz="1.16494917907219E-05"/>
    </inertial>
    <visual>
      <origin rpy="0 0 0" xyz="0 0 0"/>
      <geometry>
        <mesh filename="./meshes/kortex_description/grippers/robotiq_2f_85/meshes/visual/robotiq_arg2f_85_outer_finger.stl" scale="0.001 0.001 0.001"/>
      </geometry>
      <material name="">
        <color rgba="0.1 0.1 0.1 1"/>
      </material>
    </visual>
    <collision>
      <origin rpy="0 0 0" xyz="0 0 0"/>
      <geometry>
        <mesh filename="./meshes/kortex_description/grippers/robotiq_2f_85/meshes/collision/robotiq_arg2f_85_outer_finger.stl" scale="0.001 0.001 0.001"/>
      </geometry>
    </collision>
  </link>
  <link name="right_kinova_arm_right_inner_finger">
    <inertial>
      <origin rpy="0 0 0" xyz="0.000299999999999317 0.0160078233491243 -0.0136945669206257"/>
      <mass value="0.0104003125914103"/>
      <inertia ixx="2.71909453810972E-06" ixy="1.35402465472579E-21" ixz="-7.1817349065269E-22" iyy="7.69100314106116E-07" iyz="6.74715432769696E-07" izz="2.30315190420171E-06"/>
    </inertial>
    <visual>
      <origin rpy="0 0 0" xyz="0 0 0"/>
      <geometry>
        <mesh filename="./meshes/kortex_description/grippers/robotiq_2f_85/meshes/visual/robotiq_arg2f_85_inner_finger.stl" scale="0.001 0.001 0.001"/>
      </geometry>
      <material name="">
        <color rgba="0.1 0.1 0.1 1"/>
      </material>
    </visual>
    <collision>
      <origin rpy="0 0 0" xyz="0 0 0"/>
      <geometry>
        <mesh filename="./meshes/kortex_description/grippers/robotiq_2f_85/meshes/collision/robotiq_arg2f_85_inner_finger.stl" scale="0.001 0.001 0.001"/>
      </geometry>
    </collision>
  </link>
  <link name="right_kinova_arm_right_inner_finger_pad">
    <visual>
      <origin rpy="0 0 0" xyz="0 0 0"/>
      <geometry>
        <box size="0.022 0.00635 0.0375"/>
      </geometry>
      <material name="">
        <color rgba="0.9 0.9 0.9 1"/>
      </material>
    </visual>
    <collision>
      <origin rpy="0 0 0" xyz="0 0 0"/>
      <geometry>
        <box size="0.022 0.00635 0.0375"/>
      </geometry>
      <material name="">
        <color rgba="0.9 0.0 0.0 1"/>
      </material>
    </collision>
  </link>
  <link name="right_kinova_arm_right_inner_knuckle">
    <inertial>
      <origin rpy="0 0 0" xyz="0.000123011831763771 0.0507850843201817 0.00103968640075166"/>
      <mass value="0.0271177346495152"/>
      <inertia ixx="2.61910379223783E-05" ixy="-2.43616858946494E-07" ixz="-6.37789906117123E-09" iyy="2.8270243746167E-06" iyz="-5.37200748039765E-07" izz="2.83695868220296E-05"/>
    </inertial>
    <visual>
      <origin rpy="0 0 0" xyz="0 0 0"/>
      <geometry>
        <mesh filename="./meshes/kortex_description/grippers/robotiq_2f_85/meshes/visual/robotiq_arg2f_85_inner_knuckle.stl" scale="0.001 0.001 0.001"/>
      </geometry>
      <material name="">
        <color rgba="0.1 0.1 0.1 1"/>
      </material>
    </visual>
    <collision>
      <origin rpy="0 0 0" xyz="0 0 0"/>
      <geometry>
        <mesh filename="./meshes/kortex_description/grippers/robotiq_2f_85/meshes/collision/robotiq_arg2f_85_inner_knuckle.stl" scale="0.001 0.001 0.001"/>
      </geometry>
    </collision>
  </link>
  <joint name="right_kinova_arm_finger_joint" type="revolute">
    <origin rpy="0 0 3.141592653589793" xyz="0 -0.0306011 0.054904"/>
    <parent link="right_kinova_arm_robotiq_arg2f_base_link"/>
    <child link="right_kinova_arm_left_outer_knuckle"/>
    <axis xyz="1 0 0"/>
    <limit effort="1000" lower="0" upper="0.8" velocity="2.0"/>
  </joint>
  <joint name="right_kinova_arm_left_outer_finger_joint" type="fixed">
    <origin rpy="0 0 0" xyz="0 0.0315 -0.0041"/>
    <parent link="right_kinova_arm_left_outer_knuckle"/>
    <child link="right_kinova_arm_left_outer_finger"/>
    <axis xyz="1 0 0"/>
  </joint>
  <joint name="right_kinova_arm_left_inner_knuckle_joint" type="revolute">
    <!-- <origin xyz="0 ${reflect * -0.0127} 0.06142" rpy="${pi / 2 + .725} 0 ${(reflect - 1) * pi / 2}" /> -->
    <origin rpy="0 0 3.141592653589793" xyz="0 -0.0127 0.06142"/>
    <parent link="right_kinova_arm_robotiq_arg2f_base_link"/>
    <child link="right_kinova_arm_left_inner_knuckle"/>
    <axis xyz="1 0 0"/>
    <limit effort="1000" lower="0" upper="0.8757" velocity="2.0"/>
    <mimic joint="right_kinova_arm_finger_joint" multiplier="1" offset="0"/>
  </joint>
  <joint name="right_kinova_arm_left_inner_finger_joint" type="revolute">
    <origin rpy="0 0 0" xyz="0 0.0061 0.0471"/>
    <parent link="right_kinova_arm_left_outer_finger"/>
    <child link="right_kinova_arm_left_inner_finger"/>
    <axis xyz="1 0 0"/>
    <limit effort="1000" lower="-0.8757" upper="0.8757" velocity="2.0"/>
    <mimic joint="right_kinova_arm_finger_joint" multiplier="-1" offset="0"/>
  </joint>
  <joint name="right_kinova_arm_left_inner_finger_pad_joint" type="fixed">
    <origin rpy="0 0 0" xyz="0 -0.0220203446692936 0.03242"/>
    <parent link="right_kinova_arm_left_inner_finger"/>
    <child link="right_kinova_arm_left_inner_finger_pad"/>
    <axis xyz="0 0 1"/>
  </joint>
  <joint name="right_kinova_arm_right_outer_knuckle_joint" type="revolute">
    <origin rpy="0 0 0" xyz="0 0.0306011 0.054904"/>
    <parent link="right_kinova_arm_robotiq_arg2f_base_link"/>
    <child link="right_kinova_arm_right_outer_knuckle"/>
    <axis xyz="1 0 0"/>
    <limit effort="1000" lower="0" upper="0.81" velocity="2.0"/>
    <mimic joint="right_kinova_arm_finger_joint" multiplier="1" offset="0"/>
  </joint>
  <joint name="right_kinova_arm_right_outer_finger_joint" type="fixed">
    <origin rpy="0 0 0" xyz="0 0.0315 -0.0041"/>
    <parent link="right_kinova_arm_right_outer_knuckle"/>
    <child link="right_kinova_arm_right_outer_finger"/>
    <axis xyz="1 0 0"/>
  </joint>
  <joint name="right_kinova_arm_right_inner_knuckle_joint" type="revolute">
    <!-- <origin xyz="0 ${reflect * -0.0127} 0.06142" rpy="${pi / 2 + .725} 0 ${(reflect - 1) * pi / 2}" /> -->
    <origin rpy="0 0 0.0" xyz="0 0.0127 0.06142"/>
    <parent link="right_kinova_arm_robotiq_arg2f_base_link"/>
    <child link="right_kinova_arm_right_inner_knuckle"/>
    <axis xyz="1 0 0"/>
    <limit effort="1000" lower="0" upper="0.8757" velocity="2.0"/>
    <mimic joint="right_kinova_arm_finger_joint" multiplier="1" offset="0"/>
  </joint>
  <joint name="right_kinova_arm_right_inner_finger_joint" type="revolute">
    <origin rpy="0 0 0" xyz="0 0.0061 0.0471"/>
    <parent link="right_kinova_arm_right_outer_finger"/>
    <child link="right_kinova_arm_right_inner_finger"/>
    <axis xyz="1 0 0"/>
    <limit effort="1000" lower="-0.8757" upper="0.8757" velocity="2.0"/>
    <mimic joint="right_kinova_arm_finger_joint" multiplier="-1" offset="0"/>
  </joint>
  <joint name="right_kinova_arm_right_inner_finger_pad_joint" type="fixed">
    <origin rpy="0 0 0" xyz="0 -0.0220203446692936 0.03242"/>
    <parent link="right_kinova_arm_right_inner_finger"/>
    <child link="right_kinova_arm_right_inner_finger_pad"/>
    <axis xyz="0 0 1"/>
  </joint>
  <!-- Transmissions are loaded in the generic kortex xacro when simulation is enabled -->
  <!-- <xacro:robotiq_arg2f_transmission prefix="${prefix}"/> -->
  <joint name="left_arm_mount_joint" type="fixed">
    <origin rpy="-1.5708 0 0" xyz="0.0 0.0264 0.1914"/>
    <parent link="dual_gen3_base_link"/>
    <child link="left_kinova_arm_base_link"/>
  </joint>
  <joint name="right_arm_mount_joint" type="fixed">
    <origin rpy="1.5708 0 0" xyz="0.0 -0.0264 0.1914"/>
    <parent link="dual_gen3_base_link"/>
    <child link="right_kinova_arm_base_link"/>
  </joint>



 <link name="ptu_tilt_link">
    <inertial>
      <mass value="0.65"/>
      <origin rpy="0 0 0" xyz="0 0 0"/>
      <inertia ixx="0.0001" ixy="0" ixz="0" iyy="0.0001" iyz="0" izz="0.0001"/>
    </inertial>
    <visual>
      <material name="ptu_body_color">
        <color rgba="0.3 0.3 0.3 1.0"/>
      </material>
      <geometry>
        <mesh filename="./meshes/flir-ptu-tilt-motor.stl"/>
      </geometry>
    </visual>
    <collision>
      <geometry>
        <mesh filename="./meshes/flir-ptu-tilt-motor-collision.stl"/>
      </geometry>
    </collision>
  </link>
  <gazebo reference="ptu_tilt_link">
    <material>Gazebo/DarkGrey</material>
  </gazebo>
  <link name="ptu_pan_link">
    <inertial>
      <mass value="0.65"/>
      <origin rpy="0 0 0" xyz="0 0 0"/>
      <inertia ixx="0.0001" ixy="0" ixz="0" iyy="0.0001" iyz="0" izz="0.0001"/>
    </inertial>
    <visual>
      <material name="ptu_body_color">
        <color rgba="0.3 0.3 0.3 1.0"/>
      </material>
      <geometry>
        <mesh filename="./meshes/flir-ptu-pan-motor.stl"/>
      </geometry>
    </visual>
    <collision>
      <geometry>
        <mesh filename="./meshes/flir-ptu-pan-motor-collision.stl"/>
      </geometry>
    </collision>
  </link>
  <gazebo reference="ptu_pan_link">
    <material>Gazebo/DarkGrey</material>
  </gazebo>
  <link name="ptu_base_link">
    <inertial>
      <mass value="2e-06"/>
      <inertia ixx="1.1e-09" ixy="0" ixz="0" iyy="1.1e-09" iyz="0" izz="1.1e-09"/>
    </inertial>
  </link>
  <link name="ptu_tilted_link">
    <visual>
      <material name="ptu_body_color">
        <color rgba="0.3 0.3 0.3 1.0"/>
      </material>
      <geometry>
        <mesh filename="./meshes/flir-ptu-camera-mount.stl"/>
      </geometry>
    </visual>
    <collision>
      <geometry>
        <mesh filename="./meshes/flir-ptu-camera-mount.stl"/>
      </geometry>
    </collision>
  </link>
  <link name="ptu_mount_link">
    <inertial>
      <mass value="2e-06"/>
      <inertia ixx="1.1e-09" ixy="0" ixz="0" iyy="1.1e-09" iyz="0" izz="1.1e-09"/>
    </inertial>
  </link>
  <joint name="ptu_base" type="fixed">
    <parent link="ptu_base_link"/>
    <child link="ptu_pan_link"/>
    <origin xyz="0 0 0"/>
  </joint>
  <!-- The pan joint -->
  <joint name="ptu_pan" type="revolute">
    <parent link="ptu_pan_link"/>
    <origin rpy="-1.5708 0 0.0" xyz="0 -0.00955 0.046774"/>
    <child link="ptu_tilt_link"/>
    <axis rpy="3.14159 0 0" xyz="0 -1 0"/>
    <limit effort="30" lower="-2.775" upper="2.775" velocity="1.0"/>
  </joint>

  <!-- The tilt joint -->
  <joint name="ptu_tilt" type="revolute">
    <parent link="ptu_tilt_link"/>
    <origin rpy="-1.5708 0 0" xyz="0 -0.043713 0"/>
    <child link="ptu_tilted_link"/>
    <axis xyz="0 1 0"/>
    <limit effort="30" lower="-0.82" upper="0.52" velocity="1.0"/>
  </joint>

  <!-- Fixed joint to provide a convenient attachment point for accessories. -->
  <joint name="ptu_mount" type="fixed">
    <parent link="ptu_tilted_link"/>
    <child link="ptu_mount_link"/>
    <origin rpy="3.1416 0 0" xyz="0 0 -0.039116"/>
  </joint>
  <joint name="ptu_base_joint" type="fixed">
    <parent link="dual_gen3_base_link"/>
    <child link="ptu_base_link"/>
    <origin rpy="0 0 0" xyz="0.0 -0.002 0.2550"/>
  </joint>
  <!-- Add the realsense mount -->
  <link name="realsense_mount_link">
    <visual>
      <geometry>
        <mesh filename="./meshes/realsense_mount.stl"/>
      </geometry>
      <origin rpy="0 0 0" xyz="0 0 0"/>
    </visual>
    <collision>
      <geometry>
        <box size="0.027 0.064 0.027"/>
      </geometry>
      <origin rpy="0 0 0" xyz="-0.0009 0.0 0.0120"/>
    </collision>
  </link>
  <joint name="realsense_mount_joint" type="fixed">
    <parent link="ptu_mount_link"/>
    <child link="realsense_mount_link"/>
    <origin rpy="0 0 0" xyz="0.0005 0.0 0.0"/>
  </joint>


  <material name="aluminum">
    <color rgba="0.5 0.5 0.5 1"/>
  </material>
  <material name="plastic">
    <color rgba="0.1 0.1 0.1 1"/>
  </material>

  <!-- camera body, with origin at bottom screw mount -->
  <joint name="camera_joint" type="fixed">
    <origin rpy="0 0 0" xyz="0.0 0.0 0.005"/>
    <parent link="realsense_mount_link"/>
    <child link="camera_bottom_screw_frame"/>
  </joint>
  <link name="camera_bottom_screw_frame"/>
  <joint name="camera_link_joint" type="fixed">
    <origin rpy="0 0 0" xyz="0.010600000000000002 0.0175 0.0125"/>
    <parent link="camera_bottom_screw_frame"/>
    <child link="camera_link"/>
  </joint>
  <link name="camera_link">
    <visual>
      <!-- the mesh origin is at front plate in between the two infrared camera axes -->
      <origin rpy="1.5707963267948966 0 1.5707963267948966" xyz="0.0 -0.0175 0"/>
      <geometry>
        <mesh filename="./meshes/d415.stl"/>
      </geometry>
    </visual>
    <collision>
      <origin rpy="0 0 0" xyz="0 -0.0175 0"/>
      <geometry>
        <box size="0.02505 0.09 0.025"/>
      </geometry>
    </collision>
    <inertial>
      <!-- The following are not reliable values, and should not be used for modeling -->
      <mass value="0.072"/>
      <origin xyz="0 0 0"/>
      <inertia ixx="0.003881243" ixy="0.0" ixz="0.0" iyy="0.000498940" iyz="0.0" izz="0.003879257"/>
    </inertial>
  </link>

  
  <!-- camera depth joints and links -->
  <joint name="camera_depth_joint" type="fixed">
    <origin rpy="0 0 0" xyz="0 0 0"/>
    <parent link="camera_link"/>
    <child link="camera_depth_frame"/>
  </joint>
  <link name="camera_depth_frame"/>
  <joint name="camera_depth_optical_joint" type="fixed">
    <origin rpy="-1.5707963267948966 0 -1.5707963267948966" xyz="0 0 0"/>
    <parent link="camera_depth_frame"/>
    <child link="camera_depth_optical_frame"/>
  </joint>
  <link name="camera_depth_optical_frame"/>
  <!-- camera left IR joints and links -->
  <joint name="camera_infra1_joint" type="fixed">
    <origin rpy="0 0 0" xyz="0 0.0 0"/>
    <parent link="camera_link"/>
    <child link="camera_infra1_frame"/>
  </joint>
  <link name="camera_infra1_frame"/>
  <joint name="camera_infra1_optical_joint" type="fixed">
    <origin rpy="-1.5707963267948966 0 -1.5707963267948966" xyz="0 0 0"/>
    <parent link="camera_infra1_frame"/>
    <child link="camera_infra1_optical_frame"/>
  </joint>
  <link name="camera_infra1_optical_frame"/>
  <!-- camera right IR joints and links -->
  <joint name="camera_infra2_joint" type="fixed">
    <origin rpy="0 0 0" xyz="0 -0.05 0"/>
    <parent link="camera_link"/>
    <child link="camera_infra2_frame"/>
  </joint>
  <link name="camera_infra2_frame"/>
  <joint name="camera_infra2_optical_joint" type="fixed">
    <origin rpy="-1.5707963267948966 0 -1.5707963267948966" xyz="0 0 0"/>
    <parent link="camera_infra2_frame"/>
    <child link="camera_infra2_optical_frame"/>
  </joint>
  <link name="camera_infra2_optical_frame"/>
  <!-- camera color joints and links -->
  <joint name="camera_color_joint" type="fixed">
    <origin rpy="0 0 0" xyz="0 0.015 0"/>
    <parent link="camera_link"/>
    <child link="camera_color_frame"/>
  </joint>
  <link name="camera_color_frame"/>
  <joint name="camera_color_optical_joint" type="fixed">
    <origin rpy="-1.5707963267948966 0 -1.5707963267948966" xyz="0 0 0"/>
    <parent link="camera_color_frame"/>
    <child link="camera_color_optical_frame"/>
  </joint>
  <link name="camera_color_optical_frame"/>


</robot>

